Workbook

Sheet README
A1: STAGE 1 — DOCUMENTARY CODING WORKBOOK
A2: Version 6.0 · aligned to THE_SIMPLIFIED_PLAN_v3.8 and the web-search register v2.4
A5: THE ONE RULE | B5: You are documenting what communities SAY, what independent sources say, and what can be established historically. You are NOT judging whether a community performed well. The satellite side answers that later, and the separation between the two is what makes hypothesis H6 — claims versus delivery — meaningful.
A6: Boundary with Stage 2 | B6: Stage 1 produces coded facts. Stage 2 consumes them to build the matched control sample. Never record an eligibility VERDICT on these sheets.
A7: Blindness | B7: Do not view satellite metrics, index values or any outcome data while coding. Historical imagery is permitted ONLY to answer 'between which two image dates did a physical feature appear?', and every use is logged in O3.
A9: WHAT CHANGED IN VERSION 6.0
A10: New sheet: O11_Source_Set | B10: One row per web address per community. Most communities have more than one — a website, a Facebook page, a YouTube channel, an old domain that still holds the oldest material. Version 5 had nowhere to record which addresses were crawled and which were blocked, so 'we searched everything' could not be audited. This sheet is that audit trail, and it is what the register's Stage 0 fills.
A11: Corroboration counts GROUPS, not URLs | B11: New column independence_group in O6_Source_Index. Two sources corroborate each other only if neither is a copy of the other. A directory listing whose text came from the community's own website belongs to the SAME group as that website and counts once. Block D channel counts and the 'three independent sources' target both count groups.
A12: Decision D4 formula corrected | B12: Cohort_Tracker read the number of communities CODED, not the number of cohort candidates at confidence tier A or B. It would have printed PROCEED at community 50 whatever the cohort looked like. It now reads B6 and stays on KEEP CODING until community 100, which is what plan 11.3 actually says.
A13: The documentary area fields now link | B13: O1 is the single paste target for everything the ChatGPT register returns. O10's six documentary columns read themselves from O1, and O1's polygon_area_ha reads itself from O10. In version 5 the same fields sat in two sheets with no link, so pasting into one left the other empty — and area_agreement_tier, which decides which sites SC16 keeps, silently stayed blank.
A14: area_agreement_tier and area_ratio fixed | B14: Plan 7.1a puts a site with a polygon but NO documentary figure in tier B. The version 5 formula returned a blank, which looked identical to a site nobody had coded yet. area_ratio also displayed 0.00 on every uncoded row, because an empty numerator divides to zero rather than to an error.
A15: Four new columns in O1 | B15: documentary_area_note, independence_groups, stages_completed and crawl_truncated. They are appended at the right-hand end rather than inserted beside the fields they belong with, because inserting a column mid-sheet silently shifts every dropdown range and formula that follows it.
A16: crawl_truncated is the one that matters | B16: It records that a search stopped early. Without it an incompletely searched community is indistinguishable from a thoroughly searched one that genuinely has nothing, and the two mean opposite things.
A17: Reference_Codes brought to v3.8 | B17: The size-class block (100/150/200 m radii) and the size-class confidence block were superseded by hand-drawn polygons in plan v3.6. They are replaced by the five reference circles and the area-agreement tiers, and three new vocabularies for O11 are added.
A18: Field names match the register | B18: O1, O2, O3, O10 and O11 use exactly the field names in WEB_SEARCH_FIELD_REGISTER_AND_CHATGPT_PROMPT_v2.4, so its output pastes straight in.
A20: HOW TO USE THIS FILE
A21: Dark header row | B21: Every sheet has one, with an auto-filter. Type into the rows beneath it.
A22: Grey pre-filled rows | B22: R1_Codebook, O9_Claim_Signature_Map and O4_Reliability_Report arrive PRE-FILLED from the plan. Complete the blank columns; do not alter the pre-filled content.
A23: Italic grey EXAMPLE row | B23: Row 2 of most sheets is a worked example showing the expected format. DELETE IT before you begin.
A24: Yellow cells | B24: Cells you must fill: the freeze-control date at R1_Codebook P3, and the deposit fields in O9.
A25: Dropdowns | B25: Every controlled-vocabulary column has one. Use it. Free-typed variants ('Evidenced' vs 'evidenced') will corrupt the reliability statistics in O4.
A26: Cells that fill themselves | B26: O1 polygon_area_ha; O3 onset_band_width_years; O10 below_minimum_flag, reference_circle, area_ratio, area_agreement_tier and the six documentary columns M to R; R1 frozen_date. Do not type into them.
A27: Reference_Codes | B27: The full vocabulary with the rule behind each value, plus the list of quantities NOT to search for. Consult it rather than guessing.
A29: SEQUENCE — do not start at IC001
A30: 1–3 Freeze | B30: Complete R1_Codebook and confirm every threshold. Complete and deposit O9_Claim_Signature_Map with a timestamp. Declare every reliability threshold in O4.
A31: 4–5 Design | B31: Draw the >=20% double-coding subsample with a recorded seed, stratified by region and expected activity tier. Log the draw in R3.
A32: 6–8 Calibrate | B32: Train on communities NOT in the study sample. Record in R2. A coder proceeds only after meeting the declared threshold. THEN enter the freeze date at R1!P3.
A33: 9–11 Code | B33: Code all 212 communities. Fill O11_Source_Set for every community before coding it, so you know what you are working from. Double-code the predefined subsample after at least four weeks. Resolve every disagreement in O5 under the rule invoked, not by preference.
A34: 12 Decide | B34: At community 100, read Cohort_Tracker and make decision D4 on the longitudinal cohort.
A35: 13–14 Close | B35: Complete every sheet. Compute reliability PER VARIABLE in O4. Freeze and version the dataset, then hand it to Stage 2.
A37: EIGHT RULES MOST OFTEN BROKEN
A38: Founding year is not onset | B38: Record all four dates. Only 'environmental intervention onset' is the study's onset. A community founded 1985 that began ecological work in 1992 has an onset of 1992.
A39: Silence is not absence | B39: 'not mentioned' and 'explicitly absent' are different codes. Communities describe what they consider notable; treating silence as absence records communication style as practice.
A40: Managed area is not total holding | B40: A community holding 200 ha and working 15 ha has a managed area of 15 ha. Record both separately.
A41: Unknown is not dissolved | B41: A vanished website is not a vanished community. Dissolution requires POSITIVE evidence.
A42: Non-response is never exclusion | B42: Communities that answer unsolicited academic enquiries differ systematically from those that do not. Code from documents and widen the uncertainty band.
A43: Trace structure, never colour | B43: When drawing a community's polygon, use field edges, tracks, terraces and changes in field pattern — never greenness. A ploughed brown field is as managed as a green one. If colour influenced the drawing it does NOT cancel against the controls, because a control receives the settlement's shape translated rather than a drawing of its own.
A44: A copy is not a second source | B44: Four addresses belonging to one community are one voice, not four. Two sources corroborate only across independence groups. This is the same rule as 'two pages of one website are ONE channel', applied to the whole source set.
A45: Never accept an unverified citation | B45: For every S1 and S2 source, open the DOI or repository record yourself and set verified_resolves = yes in O6. A fabricated citation looks like your strongest evidence and will be believed.
A47: PROGRESS
...

Sheet Cohort_Tracker
A1: LONGITUDINAL COHORT TRACKER — decision D4
A2: The cohort (analysis A8) needs about 65 communities with onset in 2020 or 2021. Decide at community 100, not at the end.
A4: Communities coded so far | B4: =COUNTA(O1_Community_Attributes!A3:A500) -> 0 | D4: Excludes the example row
A5: cohort_candidate = core (2020-2021) | B5: =COUNTIF(O3_Onset_Register!Q3:Q500,"core (2020-2021)") -> 0 | D5: THE NUMBER THAT MATTERS
A6: of those, confidence tier A or B | B6: =COUNTIFS(O3_Onset_Register!Q3:Q500,"core (2020-2021)",O3_Onset_Register!O3:O500,"A")+COUNTIFS(O3_Onset_Register!Q3:Q500,"core (2020-2021)",O3_Onset_Register!O3:O500,"B") -> 0 | D6: Tier C onsets are too uncertain to anchor a before-and-after window
A7: cohort_candidate = extension (2019) | B7: =COUNTIF(O3_Onset_Register!Q3:Q500,"extension (2019)") -> 0 | D7: Usable if the core falls short — costs one pre-year
A8: cohort_candidate = uncertain | B8: =COUNTIF(O3_Onset_Register!Q3:Q500,"uncertain") -> 0 | D8: Resolve these before deciding
A10: DECISION D4 STATUS | B10: =IF(COUNTA(O1_Community_Attributes!A3:A500)<100,"KEEP CODING — decide at community 100",IF(B6>=50,"PROCEED — the component is worth its 4-6 weeks",IF(B6>=40,"PROCEED BUT REPORT AS EXPLORATORY","DROP THE COMPONENT"))) -> KEEP CODING — decide at community 100 | D10: Thresholds from plan 11.3, counted on B6 (core AND tier A or B): above 50 proceed, 40-50 exploratory, below 40 drop. CORRECTED IN v6 — v5 counted B4, the number of communities coded.
A12: Why a running tally. An underpowered before-and-after test placed beside your main result invites a reviewer to read a null as contradicting it, which it would not — but the misreading costs more than the component gains. Better to know at community 100.

Sheet O1_Community_Attributes
A1: site_id | B1: community_name_official | C1: alternative_names | D1: country | E1: admin_region | F1: latitude | G1: longitude | H1: coordinate_agreement | I1: e1_network_listing | J1: e1_pathway | K1: e1_self_identification | L1: e2_settlement_type | M1: e2_evidence_note | N1: e3_population_value | O1: e5_active_currently | P1: e8_setting_at_onset | Q1: population_value | R1: population_lower | S1: population_upper | T1: population_source_date | U1: polygon_area_ha | V1: managed_area_ha | W1: managed_area_lower_ha | X1: managed_area_upper_ha | Y1: managed_area_basis | Z1: managed_area_source_class | AA1: total_holding_ha | AB1: area_type | AC1: tenure_type | AD1: parcel_structure | AE1: site_plan_published | AF1: v1_self_documentation | AG1: v2_external_documentation | AH1: v3_substantive_affiliation | AI1: v4_visual_documentation | AJ1: v5_continuity_evidence | AK1: channel_count | AL1: activity_tier | AM1: activity_tier_note | AN1: status_current | AO1: status_evidence | AP1: first_listing_year | AQ1: last_listing_year | AR1: dissolution_year | AS1: delisting_reason | AT1: movement_tradition | AU1: founding_decade | AV1: education_volunteer_program | AW1: agricultural_orientation | AX1: external_funding_or_programme | AY1: protected_area_status | AZ1: notable_context | BA1: pages_opened_count | BB1: documents_opened | BC1: source_classes_found | BD1: search_languages | BE1: negative_consultations | BF1: coder_id | BG1: coding_date | BH1: double_coded | BI1: second_coder_id | BJ1: notes | BK1: documentary_area_note | BL1: independence_groups | BM1: stages_completed | BN1: crawl_truncated | BP1: One row per community. Field names match the ChatGPT register (v2.4) exactly, so its output pastes straight in. THIS SHEET IS THE PASTE TARGET for everything the register returns — O10 reads its six documentary area fields from here. Never record an ELIGIBILITY DECISION here; this sheet holds coded facts and Stage 2 makes the decisions.
A2: IC001 | B2: EXAMPLE ROW — DELETE BEFORE USE | C2: Quinta do Vale; Vale Farm | D2: Portugal | E2: Leiria | F2: 39.7436 | G2: -8.1245 | H2: agrees | I2: GEN Europe; national permaculture registry | J2: both | K2: regenerating this valley since the 1990s | L2: village-scale permanent residence | M2: Permanent residents on one contiguous title; not a retreat centre | N2: 28 | O2: yes | P2: rural | Q2: 28 | R2: 20 | S2: 30 | T2: 2023 | U2: 13.4 | V2: 15 | W2: 12 | X2: 18 | Y2: measured | Z2: S1 | AA2: 200 | AB2: both recorded | AC2: freehold collective | AD2: contiguous | AE2: yes — https://example.org/siteplan.pdf | AF2: yes | AG2: yes | AH2: no | AI2: yes | AJ2: yes | AK2: 4 | AL2: A | AM2: 3 channels incl. 1 external, plus continuity across 2011-2023 snapshots | AN2: active | AO2: Website updated 2025; listed in current GEN directory | AP2: 2009 | AQ2: 2025 | AS2: n/a | AT2: permaculture | AU2: 1980 | AV2: yes | AW2: mixed | AX2: LIFE grant 2014 for riparian restoration (CORDIS record) | AY2: adjacent | AZ2: none found | BA2: 31 | BB2: Annual report 2019.pdf; Site design 2012.pdf | BC2: S1;S2;S4;S5;S6 | BD2: English; Portuguese | BE2: S3 none found; S8 not attempted | BF2: RC1 | BG2: 2026-09-14 | BH2: yes | BJ2: Onset band 1990-1994 from a rank-3 retrospective statement | BK2: States 15 ha under cultivation; separate 200 ha total holding | BL2: 3 | BM2: 0-9 complete | BN2: no
U3: =IF($A3="","",IFERROR(IF(INDEX(O10_Polygon_And_Area!$C$1:$C$500,MATCH($A3,O10_Polygon_And_Area!$A$1:$A$500,0))="","",INDEX(O10_Polygon_And_Area!$C$1:$C$500,MATCH($A3,O10_Polygon_And_Area!$A$1:$A$500,0))),"")) | AK3: =IF(COUNTA(AF3:AJ3)=0,"",COUNTIF(AF3:AJ3,"yes"))
U4: =IF($A4="","",IFERROR(IF(INDEX(O10_Polygon_And_Area!$C$1:$C$500,MATCH($A4,O10_Polygon_And_Area!$A$1:$A$500,0))="","",INDEX(O10_Polygon_And_Area!$C$1:$C$500,MATCH($A4,O10_Polygon_And_Area!$A$1:$A$500,0))),"")) | AK4: =IF(COUNTA(AF4:AJ4)=0,"",COUNTIF(AF4:AJ4,"yes"))
U5: =IF($A5="","",IFERROR(IF(INDEX(O10_Polygon_And_Area!$C$1:$C$500,MATCH($A5,O10_Polygon_And_Area!$A$1:$A$500,0))="","",INDEX(O10_Polygon_And_Area!$C$1:$C$500,MATCH($A5,O10_Polygon_And_Area!$A$1:$A$500,0))),"")) | AK5: =IF(COUNTA(AF5:AJ5)=0,"",COUNTIF(AF5:AJ5,"yes"))
U6: =IF($A6="","",IFERROR(IF(INDEX(O10_Polygon_And_Area!$C$1:$C$500,MATCH($A6,O10_Polygon_And_Area!$A$1:$A$500,0))="","",INDEX(O10_Polygon_And_Area!$C$1:$C$500,MATCH($A6,O10_Polygon_And_Area!$A$1:$A$500,0))),"")) | AK6: =IF(COUNTA(AF6:AJ6)=0,"",COUNTIF(AF6:AJ6,"yes"))
U7: =IF($A7="","",IFERROR(IF(INDEX(O10_Polygon_And_Area!$C$1:$C$500,MATCH($A7,O10_Polygon_And_Area!$A$1:$A$500,0))="","",INDEX(O10_Polygon_And_Area!$C$1:$C$500,MATCH($A7,O10_Polygon_And_Area!$A$1:$A$500,0))),"")) | AK7: =IF(COUNTA(AF7:AJ7)=0,"",COUNTIF(AF7:AJ7,"yes"))
U8: =IF($A8="","",IFERROR(IF(INDEX(O10_Polygon_And_Area!$C$1:$C$500,MATCH($A8,O10_Polygon_And_Area!$A$1:$A$500,0))="","",INDEX(O10_Polygon_And_Area!$C$1:$C$500,MATCH($A8,O10_Polygon_And_Area!$A$1:$A$500,0))),"")) | AK8: =IF(COUNTA(AF8:AJ8)=0,"",COUNTIF(AF8:AJ8,"yes"))
U9: =IF($A9="","",IFERROR(IF(INDEX(O10_Polygon_And_Area!$C$1:$C$500,MATCH($A9,O10_Polygon_And_Area!$A$1:$A$500,0))="","",INDEX(O10_Polygon_And_Area!$C$1:$C$500,MATCH($A9,O10_Polygon_And_Area!$A$1:$A$500,0))),"")) | AK9: =IF(COUNTA(AF9:AJ9)=0,"",COUNTIF(AF9:AJ9,"yes"))
U10: =IF($A10="","",IFERROR(IF(INDEX(O10_Polygon_And_Area!$C$1:$C$500,MATCH($A10,O10_Polygon_And_Area!$A$1:$A$500,0))="","",INDEX(O10_Polygon_And_Area!$C$1:$C$500,MATCH($A10,O10_Polygon_And_Area!$A$1:$A$500,0))),"")) | AK10: =IF(COUNTA(AF10:AJ10)=0,"",COUNTIF(AF10:AJ10,"yes"))
U11: =IF($A11="","",IFERROR(IF(INDEX(O10_Polygon_And_Area!$C$1:$C$500,MATCH($A11,O10_Polygon_And_Area!$A$1:$A$500,0))="","",INDEX(O10_Polygon_And_Area!$C$1:$C$500,MATCH($A11,O10_Polygon_And_Area!$A$1:$A$500,0))),"")) | AK11: =IF(COUNTA(AF11:AJ11)=0,"",COUNTIF(AF11:AJ11,"yes"))
U12: =IF($A12="","",IFERROR(IF(INDEX(O10_Polygon_And_Area!$C$1:$C$500,MATCH($A12,O10_Polygon_And_Area!$A$1:$A$500,0))="","",INDEX(O10_Polygon_And_Area!$C$1:$C$500,MATCH($A12,O10_Polygon_And_Area!$A$1:$A$500,0))),"")) | AK12: =IF(COUNTA(AF12:AJ12)=0,"",COUNTIF(AF12:AJ12,"yes"))
U13: =IF($A13="","",IFERROR(IF(INDEX(O10_Polygon_And_Area!$C$1:$C$500,MATCH($A13,O10_Polygon_And_Area!$A$1:$A$500,0))="","",INDEX(O10_Polygon_And_Area!$C$1:$C$500,MATCH($A13,O10_Polygon_And_Area!$A$1:$A$500,0))),"")) | AK13: =IF(COUNTA(AF13:AJ13)=0,"",COUNTIF(AF13:AJ13,"yes"))
U14: =IF($A14="","",IFERROR(IF(INDEX(O10_Polygon_And_Area!$C$1:$C$500,MATCH($A14,O10_Polygon_And_Area!$A$1:$A$500,0))="","",INDEX(O10_Polygon_And_Area!$C$1:$C$500,MATCH($A14,O10_Polygon_And_Area!$A$1:$A$500,0))),"")) | AK14: =IF(COUNTA(AF14:AJ14)=0,"",COUNTIF(AF14:AJ14,"yes"))
... U402: =IF($A402="","",IFERROR(IF(INDEX(O10_Polygon_And_Area!$C$1:$C$500,MATCH($A402,O10_Polygon_And_Area!$A$1:$A$500,0))="","",INDEX(O10_Polygon_And_Area!$C$1:$C$500,MATCH($A402,O10_Polygon_And_Area!$A$1:$A$500,0))),"")) | AK402: =IF(COUNTA(AF402:AJ402)=0,"",COUNTIF(AF402:AJ402,"yes"))

Sheet O2_Practice_Matrix
A1: site_id | B1: community_name | C1: pc01_rainwater | D1: pc02_swales | E1: pc03_irrigation | F1: pc04_no_till | G1: pc05_mulching | H1: pc06_cover_crop | I1: pc07_tree_planting | J1: pc08_agroforestry | K1: pc09_polyculture | L1: pc10_hedgerows | M1: pc11_small_parcel | N1: pc12_organic | O1: pc13_restoration | P1: coder_id | Q1: coding_date | R1: notes | T1: THIRTEEN codes (v3.3 added pc13_restoration). Five levels only. 'not mentioned' is NOT 'explicitly absent'. Provenance for each coded cell goes in O2b.
A2: IC001 | B2: EXAMPLE ROW — DELETE BEFORE USE | C2: evidenced | D2: documented | E2: claimed | F2: documented | G2: evidenced | H2: documented | I2: evidenced | J2: evidenced | K2: documented | L2: claimed | M2: documented | N2: evidenced | O2: documented | P2: RC1 | Q2: 2026-09-14 | R2: Irrigation claimed for the nursery only; see O2b SRC0031

Sheet O2b_Practice_Evidence
A1: site_id | B1: practice_code | C1: coding_level | D1: source_id | E1: source_class | F1: full_text_or_abstract | G1: evidence_date | H1: validity_from | I1: validity_to | J1: supporting_passage | K1: coder_id | L1: notes | N1: One row per CODED practice per site (levels evidenced/documented/claimed/explicitly absent). 'not mentioned' needs no row. An ACADEMIC or GREY source is what upgrades a code from 'claimed' to 'evidenced'.
A2: IC001 | B2: pc08_agroforestry | C2: evidenced | D2: SRC0012 | E2: S1 | F2: full text | G2: 2019 | H2: 2016 | J2: Describes a 1.8 ha seven-layer food forest established from 2016 | K2: RC1 | L2: validity_to blank = still current at the source date

Sheet O3_Onset_Register
A1: site_id | B1: community_name | C1: date_formal_founding | D1: date_land_acquisition | E1: date_first_residence | F1: date_intervention_onset | G1: onset_lower_bound | H1: onset_upper_bound | I1: onset_band_width_years | J1: onset_evidence_rank | K1: onset_evidence_description | L1: onset_conflicting_sources | M1: resolution_rule | N1: onset_proxy_flag | O1: onset_confidence_tier | P1: onset_first_or_major | Q1: cohort_candidate | R1: domain_onsets | S1: source_ids | T1: coder_id | U1: coding_date | V1: notes | X1: Four candidate dates are all retained. ONLY date_intervention_onset is the study's onset. Rank 5 (a directory founding year) is a PROXY, never a true onset. Almost every RANK 1 source comes from academic or grey literature — see O7_Search_Log.
A2: IC001 | B2: EXAMPLE ROW — DELETE BEFORE USE | C2: 1985 | D2: 1987 | E2: 1988 | F2: 1992 | G2: 1990 | H2: 1994 | J2: 3 | K2: Community 20th-anniversary timeline, dated 2012 | L2: Website says 1990, newsletter says 1992 | M2: Equal rank: earlier year as point estimate, the gap becomes the band | N2: no | O2: B | P2: first intervention | Q2: no | R2: water 1998; vegetation 1992; soil 1995 | S2: SRC0007; SRC0012 | T2: RC1 | U2: 2026-09-14 | V2: Overall onset = earliest domain onset (vegetation 1992)
I3: =IFERROR(H3-G3,"") -> 0
I4: =IFERROR(H4-G4,"") -> 0
I5: =IFERROR(H5-G5,"") -> 0
I6: =IFERROR(H6-G6,"") -> 0
I7: =IFERROR(H7-G7,"") -> 0
I8: =IFERROR(H8-G8,"") -> 0
I9: =IFERROR(H9-G9,"") -> 0
I10: =IFERROR(H10-G10,"") -> 0
I11: =IFERROR(H11-G11,"") -> 0
I12: =IFERROR(H12-G12,"") -> 0
I13: =IFERROR(H13-G13,"") -> 0
I14: =IFERROR(H14-G14,"") -> 0
... I402: =IFERROR(H402-G402,"") -> 0

Sheet O4_Reliability_Report
A1: variable | B1: variable_type | C1: agreement_method | D1: threshold_declared | E1: raw_agreement | F1: agreement_coefficient | G1: icc | H1: mean_absolute_difference | I1: within_uncertainty_band | J1: marginal_distribution_notes | K1: calibration_start | L1: calibration_midpoint | M1: calibration_end | N1: drift_result | O1: action_if_below_threshold | P1: notes | R1: PRE-FILLED with the variables THE_SIMPLIFIED_PLAN_v3.8 requires. Report reliability PER VARIABLE — never one figure for the whole codebook. Add 13 rows for the individual practice codes when you compute them.
A2: date_intervention_onset | B2: date | C2: ICC + mean absolute difference + agreement within band | D2: declared before coding | J2: Report MAD in YEARS beside the coefficient | O2: Revise the codebook definition, re-code this variable in full, report both figures
A3: onset_evidence_rank | B3: ordered categorical | C3: weighted chance-corrected agreement | D3: declared before coding | J3: Weights disagreements by distance between ranks
A4: onset_confidence_tier | B4: ordered categorical | C4: weighted chance-corrected agreement | D4: declared before coding | J4: Load-bearing for the longitudinal cohort (decision D4)
A5: cohort_candidate | B5: categorical | C5: chance-corrected agreement | D5: declared before coding | J5: Determines which communities enter analysis A8
A6: activity_tier | B6: ordered categorical | C6: weighted chance-corrected agreement | D6: declared before coding | J6: Report the marginal distribution: tiers are usually skewed
A7: managed_area_ha | B7: continuous | C7: ICC + mean absolute difference | D7: declared before coding | J7: Report MAD in HECTARES. Since plan v3.6 this CORROBORATES the drawn polygon rather than setting geometry: it produces area_agreement_tier and table T8b, and SC16 restricts to tier A.
A8: polygon_area_ha | B8: continuous | C8: ICC + mean absolute difference, from the 20% redraw | D8: declared before coding | J8: Report MAD in HECTARES. This is the reliability figure for the study's PRIMARY MEASUREMENT GEOMETRY
A9: polygon_iou (redraw overlap) | B9: continuous | C9: mean overlap, and the count below 0.80 | D9: declared before coding | J9: Shared area / combined area between your two drawings. Below a mean of 0.80, report SC1 (circles) as primary instead
A10: reference_circle | B10: ordered categorical | C10: weighted chance-corrected agreement | D10: declared before coding | J10: Derived from polygon area, so its reliability follows the polygon's
A11: population_value | B11: continuous | C11: ICC + mean absolute difference | D11: declared before coding
A12: status_current | B12: categorical | C12: chance-corrected agreement | D12: declared before coding
A13: practice codes (each of THIRTEEN, reported separately) | B13: categorical | C13: chance-corrected agreement | D13: see R1_Codebook per code | J13: Where a code is strongly skewed, report raw agreement and the marginal distribution beside the coefficient

Sheet O5_Disagreement_Log
A1: disagreement_id | B1: site_id | C1: variable | D1: coder_1_value | E1: coder_2_value | F1: evidence_in_question | G1: rule_invoked | H1: resolution_type | I1: third_coder | J1: final_value | K1: codebook_amended | L1: re_coding_required | M1: date_resolved | N1: notes | P1: Every disagreement and its resolution. The disagreement RATE is itself a reported diagnostic.
A2: DIS001 | B2: IC001 | C2: onset_evidence_rank | D2: 3 | E2: 2 | F2: Archived 2011 snapshot: does it describe work as ALREADY under way? | G2: Rank 2 requires the work be described as already under way | H2: rule applied | J2: 3 | K2: no | L2: no | M2: 2026-09-20 | N2: Snapshot announced an intention, not work in progress

Sheet O6_Source_Index
A1: source_id | B1: site_id | C1: source_class | D1: source_type | E1: title | F1: url_or_reference | G1: publication_or_snapshot_date | H1: retrieval_date | I1: full_text_or_abstract | J1: specific_passage_or_page | K1: value_supported | L1: language | M1: translation_used | N1: doi_or_identifier | O1: verified_resolves | P1: notes | Q1: independence_group | S1: One row per source. VERIFIED_RESOLVES is mandatory for every S1 and S2 source: open the DOI or repository record yourself and confirm it exists. A fabricated citation looks like your strongest evidence and will be believed. INDEPENDENCE_GROUP: sources that derive from the same underlying statement share one group id. A directory listing copied from the community's website is the SAME group as that website. Corroboration counts groups, not URLs.
A2: SRC0012 | B2: IC001 | C2: S1 | D2: peer-reviewed paper | E2: Agroecological transition at a Portuguese ecovillage | F2: https://doi.org/10.xxxx/example | G2: 2019 | H2: 2026-09-10 | I2: full text | J2: p.114, Table 2 and Fig. 3 | K2: pc08_agroforestry = evidenced; intervention onset >= 2016 | L2: Portuguese | M2: yes | N2: 10.xxxx/example | O2: yes | P2: Archived copy retained locally; only this provenance row is deposited | Q2: G1

Sheet O7_Search_Log
A1: site_id | B1: database_or_source | C1: database_type | D1: search_strings_used | E1: language | F1: hits_returned | G1: full_text_opened | H1: abstract_only | I1: result | J1: date_searched | K1: coder_id | L1: notes | N1: One row per database per site — INCLUDING those that returned nothing. A recorded negative consultation is what makes 'no academic literature exists' a finding rather than an absence of effort. Log every database named in Stages 5 and 6 of the ChatGPT prompt. Web ADDRESSES belong in O11_Source_Set, not here: this sheet is for databases searched.
A2: IC001 | B2: Google Scholar | C2: academic | D2: "Quinta do Vale" ecovillage; Vale Farm permaculture; Leiria intentional community | E2: English; Portuguese | F2: 4 | G2: 2 | H2: 1 | I2: hits found | J2: 2026-09-10 | K2: RC1 | L2: Two papers relevant; one behind a paywall, abstract only

Sheet O8_Enquiry_Record
A1: enquiry_id | B1: site_id | C1: reason_for_contact | D1: date_sent | E1: medium | F1: response_status | G1: date_responded | H1: consent_to_answer | I1: consent_to_identification | J1: consent_to_location_disclosure | K1: withdrawal_request | L1: onset_information | M1: managed_area_information | N1: other_facts_supplied | O1: source_class | P1: personal_identifiers_retained | Q1: ethics_reference | R1: coder_id | S1: notes | U1: Decision D1 recommends coding from PUBLISHED SOURCES ONLY, contacting only communities whose onset stays undeterminable — usually a small number. If you contact nobody, this sheet stays empty and no ethics application is needed. Consent is THREE separate permissions; silence is never consent; non-response is NEVER an exclusion.
A2: ENQ001 | B2: IC001 | C2: Onset undeterminable from published sources | D2: 2026-10-14 | E2: email | F2: responded | G2: 2026-10-21 | H2: yes | I2: yes | J2: no | K2: no | L2: Confirms first planting 1992 | M2: Manages 15 ha of 200 ha held | N2: Two parcels, one contiguous block | O2: S8 | P2: no | Q2: REC-2026-014 | R2: RC1 | S2: Location disclosure withheld -> restricted tier

Sheet O9_Claim_Signature_Map
A1: claim_code | B1: practice_code | C1: practice_label | D1: predicted_signature | E1: mapped_metric_or_flag | F1: mapping_version | G1: deposit_timestamp | H1: approved_before_coding | I1: notes | K1: PRE-FILLED from THE_SIMPLIFIED_PLAN and unchanged through v3.8 — mapping_version stays 1.0 because the mapping itself has not moved. MUST be deposited with a timestamp BEFORE any coding begins and before any index value exists. Fill deposit_timestamp and approved_before_coding, then do NOT alter the mapping. This is what makes hypothesis H6 falsifiable.
A2: CS01 | B2: pc01_rainwater | C2: Rainwater harvesting | D2: Water-subsidy flag NOT raised | E2: Water-subsidy flag (FC1+FC2) | F2: 1.0
A3: CS02 | B3: pc02_swales | C3: Swales, keyline earthworks, contour water works | D3: HIGHER CONTOUR ALIGNMENT (CA) - the most practice-specific prediction in the codebook. Also: water-subsidy flag not raised; higher dry-season minimum NDVI (VM3) | E3: CA contour alignment (SC15); FC1/FC2; VM3 | F3: 1.0
A4: CS03 | B4: pc03_irrigation | C4: Irrigation used | D4: Water-subsidy flag RAISED. A claim predicting an UNFAVOURABLE signature - included so the instrument is not one-sided | E4: Water-subsidy flag (FC1+FC2) | F4: 1.0
A5: CS04 | B5: pc04_no_till | C5: No-till or minimum tillage | D5: Disturbance flag not raised; lower bare-ground fraction (VM6) | E5: Disturbance flag (FC3+FC4); VM6 | F5: 1.0
A6: CS05 | B6: pc05_mulching | C6: Permanent ground cover and mulching | D6: Longer green cover duration (VM5); lower bare-ground fraction (VM6) | E6: VM5; VM6 | F6: 1.0
A7: CS06 | B7: pc06_cover_crop | C7: Cover cropping or green manure | D7: Longer green cover duration (VM5) | E7: VM5 | F7: 1.0
A8: CS07 | B8: pc07_tree_planting | C8: Tree planting or reforestation | D8: Higher canopy height (VM8) and woody cover (VM9), conditional on onset age | E8: VM8; VM9 | F8: 1.0
A9: CS08 | B9: pc08_agroforestry | C9: Food forest or agroforestry | D9: Higher structure score; higher phenological asynchrony (VM11) | E9: VCI-T structure; VM11 | F9: 1.0
A10: CS09 | B10: pc09_polyculture | C10: Perennial polyculture | D10: Higher phenological asynchrony (VM11); higher spectral diversity (VM10) | E10: VM11; VM10 | F10: 1.0
A11: CS10 | B11: pc10_hedgerows | C11: Hedgerows and windbreaks | D11: Higher edge density (VM12). NOTE: a 2-4 m hedgerow is SUB-PIXEL, so only a network dense enough to change field-scale pattern is detectable | E11: VM12 | F11: 1.0
A12: CS11 | B12: pc11_small_parcel | C12: Small-parcel diversified planting | D12: Higher spectral diversity (VM10); higher edge density (VM12) | E12: VM10; VM12 | F12: 1.0
A13: CS12 | B13: pc12_organic | C13: Organic or no synthetic inputs | D13: Reported DESCRIPTIVELY ONLY - this study has no input-intensity flag, so no signature is predicted | E13: none - descriptive only | F13: 1.0
A14: CS13 | B14: pc13_restoration | C14: Land restoration or rehabilitation, NON-TREE | D14: Lower bare-ground fraction (VM6); longer green cover duration (VM5); higher dry-season minimum NDVI (VM3) | E14: VM6; VM5; VM3 | F14: 1.0

Sheet O10_Polygon_And_Area
A1: site_id | B1: community_name | C1: polygon_area_ha | D1: polygon_file_id | E1: polygon_imagery_date | F1: polygon_imagery_source | G1: polygon_confidence | H1: below_minimum_flag | I1: reference_circle | J1: polygon_redrawn | K1: redraw_area_ha | L1: polygon_iou | M1: managed_area_ha | N1: managed_area_lower_ha | O1: managed_area_upper_ha | P1: managed_area_basis | Q1: managed_area_source_class | R1: documentary_area_note | S1: area_ratio | T1: area_agreement_tier | U1: agreement_note | V1: controls_translated | W1: drawn_by | X1: drawn_date | Y1: redraw_date | Z1: notes | AB1: HOW THIS SHEET WORKS — plan 7.1a
A2: IC001 | B2: EXAMPLE ROW — DELETE BEFORE USE | C2: 13.4 | D2: POLY_IC001 | E2: 2023-07-11 | F2: Google Earth | G2: clear | J2: yes | K2: 12.8 | L2: 0.91 | M2: 15 | N2: 12 | O2: 18 | P2: measured | Q2: S1 | R2: States 15 ha under cultivation; separate 200 ha total holding | U2: Drawn 13.4 ha against a stated 15 ha — within 30% | V2: yes | W2: RC1 | X2: 2026-09-14 | Y2: 2026-10-19 | Z2: Long valley strip; a 150 m circle would have caught under half of it | AB2: 1. DRAW one polygon per settlement on high-resolution imagery. Follow the real outline — a strip if the land is a strip.
H3: =IF(C3="","",IF(C3<1,"yes","no")) | I3: =IF(C3="","",IF(C3<2.6,"r75",IF(C3<5.2,"r110",IF(C3<9.9,"r150",IF(C3<19.8,"r210","r300"))))) | M3: =IF($A3="","",IFERROR(IF(INDEX(O1_Community_Attributes!$V$1:$V$500,MATCH($A3,O1_Community_Attributes!$A$1:$A$500,0))="","",INDEX(O1_Community_Attributes!$V$1:$V$500,MATCH($A3,O1_Community_Attributes!$A$1:$A$500,0))),"")) | N3: =IF($A3="","",IFERROR(IF(INDEX(O1_Community_Attributes!$W$1:$W$500,MATCH($A3,O1_Community_Attributes!$A$1:$A$500,0))="","",INDEX(O1_Community_Attributes!$W$1:$W$500,MATCH($A3,O1_Community_Attributes!$A$1:$A$500,0))),"")) | O3: =IF($A3="","",IFERROR(IF(INDEX(O1_Community_Attributes!$X$1:$X$500,MATCH($A3,O1_Community_Attributes!$A$1:$A$500,0))="","",INDEX(O1_Community_Attributes!$X$1:$X$500,MATCH($A3,O1_Community_Attributes!$A$1:$A$500,0))),"")) | P3: =IF($A3="","",IFERROR(IF(INDEX(O1_Community_Attributes!$Y$1:$Y$500,MATCH($A3,O1_Community_Attributes!$A$1:$A$500,0))="","",INDEX(O1_Community_Attributes!$Y$1:$Y$500,MATCH($A3,O1_Community_Attributes!$A$1:$A$500,0))),"")) | Q3: =IF($A3="","",IFERROR(IF(INDEX(O1_Community_Attributes!$Z$1:$Z$500,MATCH($A3,O1_Community_Attributes!$A$1:$A$500,0))="","",INDEX(O1_Community_Attributes!$Z$1:$Z$500,MATCH($A3,O1_Community_Attributes!$A$1:$A$500,0))),"")) | R3: =IF($A3="","",IFERROR(IF(INDEX(O1_Community_Attributes!$BK$1:$BK$500,MATCH($A3,O1_Community_Attributes!$A$1:$A$500,0))="","",INDEX(O1_Community_Attributes!$BK$1:$BK$500,MATCH($A3,O1_Community_Attributes!$A$1:$A$500,0))),"")) | S3: =IF(OR($C3="",$M3=""),"",$M3/$C3) | T3: =IF($C3="","",IF(AND($M3="",$P3=""),"",IF($M3="","B",IF(ABS($S3-1)<=0.3,"A",IF(OR($S3>2,$S3<0.5),"C","B"))))) | AB3: 2. DRAW FROM STRUCTURE, NEVER COLOUR. Field edges, tracks, walls, terrace lines, changes in field pattern.
H4: =IF(C4="","",IF(C4<1,"yes","no")) | I4: =IF(C4="","",IF(C4<2.6,"r75",IF(C4<5.2,"r110",IF(C4<9.9,"r150",IF(C4<19.8,"r210","r300"))))) | M4: =IF($A4="","",IFERROR(IF(INDEX(O1_Community_Attributes!$V$1:$V$500,MATCH($A4,O1_Community_Attributes!$A$1:$A$500,0))="","",INDEX(O1_Community_Attributes!$V$1:$V$500,MATCH($A4,O1_Community_Attributes!$A$1:$A$500,0))),"")) | N4: =IF($A4="","",IFERROR(IF(INDEX(O1_Community_Attributes!$W$1:$W$500,MATCH($A4,O1_Community_Attributes!$A$1:$A$500,0))="","",INDEX(O1_Community_Attributes!$W$1:$W$500,MATCH($A4,O1_Community_Attributes!$A$1:$A$500,0))),"")) | O4: =IF($A4="","",IFERROR(IF(INDEX(O1_Community_Attributes!$X$1:$X$500,MATCH($A4,O1_Community_Attributes!$A$1:$A$500,0))="","",INDEX(O1_Community_Attributes!$X$1:$X$500,MATCH($A4,O1_Community_Attributes!$A$1:$A$500,0))),"")) | P4: =IF($A4="","",IFERROR(IF(INDEX(O1_Community_Attributes!$Y$1:$Y$500,MATCH($A4,O1_Community_Attributes!$A$1:$A$500,0))="","",INDEX(O1_Community_Attributes!$Y$1:$Y$500,MATCH($A4,O1_Community_Attributes!$A$1:$A$500,0))),"")) | Q4: =IF($A4="","",IFERROR(IF(INDEX(O1_Community_Attributes!$Z$1:$Z$500,MATCH($A4,O1_Community_Attributes!$A$1:$A$500,0))="","",INDEX(O1_Community_Attributes!$Z$1:$Z$500,MATCH($A4,O1_Community_Attributes!$A$1:$A$500,0))),"")) | R4: =IF($A4="","",IFERROR(IF(INDEX(O1_Community_Attributes!$BK$1:$BK$500,MATCH($A4,O1_Community_Attributes!$A$1:$A$500,0))="","",INDEX(O1_Community_Attributes!$BK$1:$BK$500,MATCH($A4,O1_Community_Attributes!$A$1:$A$500,0))),"")) | S4: =IF(OR($C4="",$M4=""),"",$M4/$C4) | T4: =IF($C4="","",IF(AND($M4="",$P4=""),"",IF($M4="","B",IF(ABS($S4-1)<=0.3,"A",IF(OR($S4>2,$S4<0.5),"C","B"))))) | AB4: 3. MINIMUM 1.0 ha. Below that use a 75 m circle instead — below_minimum_flag fills itself.
H5: =IF(C5="","",IF(C5<1,"yes","no")) | I5: =IF(C5="","",IF(C5<2.6,"r75",IF(C5<5.2,"r110",IF(C5<9.9,"r150",IF(C5<19.8,"r210","r300"))))) | M5: =IF($A5="","",IFERROR(IF(INDEX(O1_Community_Attributes!$V$1:$V$500,MATCH($A5,O1_Community_Attributes!$A$1:$A$500,0))="","",INDEX(O1_Community_Attributes!$V$1:$V$500,MATCH($A5,O1_Community_Attributes!$A$1:$A$500,0))),"")) | N5: =IF($A5="","",IFERROR(IF(INDEX(O1_Community_Attributes!$W$1:$W$500,MATCH($A5,O1_Community_Attributes!$A$1:$A$500,0))="","",INDEX(O1_Community_Attributes!$W$1:$W$500,MATCH($A5,O1_Community_Attributes!$A$1:$A$500,0))),"")) | O5: =IF($A5="","",IFERROR(IF(INDEX(O1_Community_Attributes!$X$1:$X$500,MATCH($A5,O1_Community_Attributes!$A$1:$A$500,0))="","",INDEX(O1_Community_Attributes!$X$1:$X$500,MATCH($A5,O1_Community_Attributes!$A$1:$A$500,0))),"")) | P5: =IF($A5="","",IFERROR(IF(INDEX(O1_Community_Attributes!$Y$1:$Y$500,MATCH($A5,O1_Community_Attributes!$A$1:$A$500,0))="","",INDEX(O1_Community_Attributes!$Y$1:$Y$500,MATCH($A5,O1_Community_Attributes!$A$1:$A$500,0))),"")) | Q5: =IF($A5="","",IFERROR(IF(INDEX(O1_Community_Attributes!$Z$1:$Z$500,MATCH($A5,O1_Community_Attributes!$A$1:$A$500,0))="","",INDEX(O1_Community_Attributes!$Z$1:$Z$500,MATCH($A5,O1_Community_Attributes!$A$1:$A$500,0))),"")) | R5: =IF($A5="","",IFERROR(IF(INDEX(O1_Community_Attributes!$BK$1:$BK$500,MATCH($A5,O1_Community_Attributes!$A$1:$A$500,0))="","",INDEX(O1_Community_Attributes!$BK$1:$BK$500,MATCH($A5,O1_Community_Attributes!$A$1:$A$500,0))),"")) | S5: =IF(OR($C5="",$M5=""),"",$M5/$C5) | T5: =IF($C5="","",IF(AND($M5="",$P5=""),"",IF($M5="","B",IF(ABS($S5-1)<=0.3,"A",IF(OR($S5>2,$S5<0.5),"C","B"))))) | AB5: 4. TRANSLATE the polygon onto each of the 3 controls: slide it so its centre sits on the control village. No resizing, no reshaping, NO ROTATION.
H6: =IF(C6="","",IF(C6<1,"yes","no")) | I6: =IF(C6="","",IF(C6<2.6,"r75",IF(C6<5.2,"r110",IF(C6<9.9,"r150",IF(C6<19.8,"r210","r300"))))) | M6: =IF($A6="","",IFERROR(IF(INDEX(O1_Community_Attributes!$V$1:$V$500,MATCH($A6,O1_Community_Attributes!$A$1:$A$500,0))="","",INDEX(O1_Community_Attributes!$V$1:$V$500,MATCH($A6,O1_Community_Attributes!$A$1:$A$500,0))),"")) | N6: =IF($A6="","",IFERROR(IF(INDEX(O1_Community_Attributes!$W$1:$W$500,MATCH($A6,O1_Community_Attributes!$A$1:$A$500,0))="","",INDEX(O1_Community_Attributes!$W$1:$W$500,MATCH($A6,O1_Community_Attributes!$A$1:$A$500,0))),"")) | O6: =IF($A6="","",IFERROR(IF(INDEX(O1_Community_Attributes!$X$1:$X$500,MATCH($A6,O1_Community_Attributes!$A$1:$A$500,0))="","",INDEX(O1_Community_Attributes!$X$1:$X$500,MATCH($A6,O1_Community_Attributes!$A$1:$A$500,0))),"")) | P6: =IF($A6="","",IFERROR(IF(INDEX(O1_Community_Attributes!$Y$1:$Y$500,MATCH($A6,O1_Community_Attributes!$A$1:$A$500,0))="","",INDEX(O1_Community_Attributes!$Y$1:$Y$500,MATCH($A6,O1_Community_Attributes!$A$1:$A$500,0))),"")) | Q6: =IF($A6="","",IFERROR(IF(INDEX(O1_Community_Attributes!$Z$1:$Z$500,MATCH($A6,O1_Community_Attributes!$A$1:$A$500,0))="","",INDEX(O1_Community_Attributes!$Z$1:$Z$500,MATCH($A6,O1_Community_Attributes!$A$1:$A$500,0))),"")) | R6: =IF($A6="","",IFERROR(IF(INDEX(O1_Community_Attributes!$BK$1:$BK$500,MATCH($A6,O1_Community_Attributes!$A$1:$A$500,0))="","",INDEX(O1_Community_Attributes!$BK$1:$BK$500,MATCH($A6,O1_Community_Attributes!$A$1:$A$500,0))),"")) | S6: =IF(OR($C6="",$M6=""),"",$M6/$C6) | T6: =IF($C6="","",IF(AND($M6="",$P6=""),"",IF($M6="","B",IF(ABS($S6-1)<=0.3,"A",IF(OR($S6>2,$S6<0.5),"C","B"))))) | AB6: 5. REDRAW a random 20% after four weeks without looking at your first version. polygon_iou is the overlap: shared area / combined area.
H7: =IF(C7="","",IF(C7<1,"yes","no")) | I7: =IF(C7="","",IF(C7<2.6,"r75",IF(C7<5.2,"r110",IF(C7<9.9,"r150",IF(C7<19.8,"r210","r300"))))) | M7: =IF($A7="","",IFERROR(IF(INDEX(O1_Community_Attributes!$V$1:$V$500,MATCH($A7,O1_Community_Attributes!$A$1:$A$500,0))="","",INDEX(O1_Community_Attributes!$V$1:$V$500,MATCH($A7,O1_Community_Attributes!$A$1:$A$500,0))),"")) | N7: =IF($A7="","",IFERROR(IF(INDEX(O1_Community_Attributes!$W$1:$W$500,MATCH($A7,O1_Community_Attributes!$A$1:$A$500,0))="","",INDEX(O1_Community_Attributes!$W$1:$W$500,MATCH($A7,O1_Community_Attributes!$A$1:$A$500,0))),"")) | O7: =IF($A7="","",IFERROR(IF(INDEX(O1_Community_Attributes!$X$1:$X$500,MATCH($A7,O1_Community_Attributes!$A$1:$A$500,0))="","",INDEX(O1_Community_Attributes!$X$1:$X$500,MATCH($A7,O1_Community_Attributes!$A$1:$A$500,0))),"")) | P7: =IF($A7="","",IFERROR(IF(INDEX(O1_Community_Attributes!$Y$1:$Y$500,MATCH($A7,O1_Community_Attributes!$A$1:$A$500,0))="","",INDEX(O1_Community_Attributes!$Y$1:$Y$500,MATCH($A7,O1_Community_Attributes!$A$1:$A$500,0))),"")) | Q7: =IF($A7="","",IFERROR(IF(INDEX(O1_Community_Attributes!$Z$1:$Z$500,MATCH($A7,O1_Community_Attributes!$A$1:$A$500,0))="","",INDEX(O1_Community_Attributes!$Z$1:$Z$500,MATCH($A7,O1_Community_Attributes!$A$1:$A$500,0))),"")) | R7: =IF($A7="","",IFERROR(IF(INDEX(O1_Community_Attributes!$BK$1:$BK$500,MATCH($A7,O1_Community_Attributes!$A$1:$A$500,0))="","",INDEX(O1_Community_Attributes!$BK$1:$BK$500,MATCH($A7,O1_Community_Attributes!$A$1:$A$500,0))),"")) | S7: =IF(OR($C7="",$M7=""),"",$M7/$C7) | T7: =IF($C7="","",IF(AND($M7="",$P7=""),"",IF($M7="","B",IF(ABS($S7-1)<=0.3,"A",IF(OR($S7>2,$S7<0.5),"C","B"))))) | AB7: 6. The documentary figure is the CHECK. area_ratio and area_agreement_tier fill themselves: within 30% = A, 30-100% apart = B, more than 2x apart = C, investigate.
H8: =IF(C8="","",IF(C8<1,"yes","no")) | I8: =IF(C8="","",IF(C8<2.6,"r75",IF(C8<5.2,"r110",IF(C8<9.9,"r150",IF(C8<19.8,"r210","r300"))))) | M8: =IF($A8="","",IFERROR(IF(INDEX(O1_Community_Attributes!$V$1:$V$500,MATCH($A8,O1_Community_Attributes!$A$1:$A$500,0))="","",INDEX(O1_Community_Attributes!$V$1:$V$500,MATCH($A8,O1_Community_Attributes!$A$1:$A$500,0))),"")) | N8: =IF($A8="","",IFERROR(IF(INDEX(O1_Community_Attributes!$W$1:$W$500,MATCH($A8,O1_Community_Attributes!$A$1:$A$500,0))="","",INDEX(O1_Community_Attributes!$W$1:$W$500,MATCH($A8,O1_Community_Attributes!$A$1:$A$500,0))),"")) | O8: =IF($A8="","",IFERROR(IF(INDEX(O1_Community_Attributes!$X$1:$X$500,MATCH($A8,O1_Community_Attributes!$A$1:$A$500,0))="","",INDEX(O1_Community_Attributes!$X$1:$X$500,MATCH($A8,O1_Community_Attributes!$A$1:$A$500,0))),"")) | P8: =IF($A8="","",IFERROR(IF(INDEX(O1_Community_Attributes!$Y$1:$Y$500,MATCH($A8,O1_Community_Attributes!$A$1:$A$500,0))="","",INDEX(O1_Community_Attributes!$Y$1:$Y$500,MATCH($A8,O1_Community_Attributes!$A$1:$A$500,0))),"")) | Q8: =IF($A8="","",IFERROR(IF(INDEX(O1_Community_Attributes!$Z$1:$Z$500,MATCH($A8,O1_Community_Attributes!$A$1:$A$500,0))="","",INDEX(O1_Community_Attributes!$Z$1:$Z$500,MATCH($A8,O1_Community_Attributes!$A$1:$A$500,0))),"")) | R8: =IF($A8="","",IFERROR(IF(INDEX(O1_Community_Attributes!$BK$1:$BK$500,MATCH($A8,O1_Community_Attributes!$A$1:$A$500,0))="","",INDEX(O1_Community_Attributes!$BK$1:$BK$500,MATCH($A8,O1_Community_Attributes!$A$1:$A$500,0))),"")) | S8: =IF(OR($C8="",$M8=""),"",$M8/$C8) | T8: =IF($C8="","",IF(AND($M8="",$P8=""),"",IF($M8="","B",IF(ABS($S8-1)<=0.3,"A",IF(OR($S8>2,$S8<0.5),"C","B")))))
H9: =IF(C9="","",IF(C9<1,"yes","no")) | I9: =IF(C9="","",IF(C9<2.6,"r75",IF(C9<5.2,"r110",IF(C9<9.9,"r150",IF(C9<19.8,"r210","r300"))))) | M9: =IF($A9="","",IFERROR(IF(INDEX(O1_Community_Attributes!$V$1:$V$500,MATCH($A9,O1_Community_Attributes!$A$1:$A$500,0))="","",INDEX(O1_Community_Attributes!$V$1:$V$500,MATCH($A9,O1_Community_Attributes!$A$1:$A$500,0))),"")) | N9: =IF($A9="","",IFERROR(IF(INDEX(O1_Community_Attributes!$W$1:$W$500,MATCH($A9,O1_Community_Attributes!$A$1:$A$500,0))="","",INDEX(O1_Community_Attributes!$W$1:$W$500,MATCH($A9,O1_Community_Attributes!$A$1:$A$500,0))),"")) | O9: =IF($A9="","",IFERROR(IF(INDEX(O1_Community_Attributes!$X$1:$X$500,MATCH($A9,O1_Community_Attributes!$A$1:$A$500,0))="","",INDEX(O1_Community_Attributes!$X$1:$X$500,MATCH($A9,O1_Community_Attributes!$A$1:$A$500,0))),"")) | P9: =IF($A9="","",IFERROR(IF(INDEX(O1_Community_Attributes!$Y$1:$Y$500,MATCH($A9,O1_Community_Attributes!$A$1:$A$500,0))="","",INDEX(O1_Community_Attributes!$Y$1:$Y$500,MATCH($A9,O1_Community_Attributes!$A$1:$A$500,0))),"")) | Q9: =IF($A9="","",IFERROR(IF(INDEX(O1_Community_Attributes!$Z$1:$Z$500,MATCH($A9,O1_Community_Attributes!$A$1:$A$500,0))="","",INDEX(O1_Community_Attributes!$Z$1:$Z$500,MATCH($A9,O1_Community_Attributes!$A$1:$A$500,0))),"")) | R9: =IF($A9="","",IFERROR(IF(INDEX(O1_Community_Attributes!$BK$1:$BK$500,MATCH($A9,O1_Community_Attributes!$A$1:$A$500,0))="","",INDEX(O1_Community_Attributes!$BK$1:$BK$500,MATCH($A9,O1_Community_Attributes!$A$1:$A$500,0))),"")) | S9: =IF(OR($C9="",$M9=""),"",$M9/$C9) | T9: =IF($C9="","",IF(AND($M9="",$P9=""),"",IF($M9="","B",IF(ABS($S9-1)<=0.3,"A",IF(OR($S9>2,$S9<0.5),"C","B"))))) | AB9: The POLYGON always defines the geometry. The documentary figure only says how well corroborated it is.
H10: =IF(C10="","",IF(C10<1,"yes","no")) | I10: =IF(C10="","",IF(C10<2.6,"r75",IF(C10<5.2,"r110",IF(C10<9.9,"r150",IF(C10<19.8,"r210","r300"))))) | M10: =IF($A10="","",IFERROR(IF(INDEX(O1_Community_Attributes!$V$1:$V$500,MATCH($A10,O1_Community_Attributes!$A$1:$A$500,0))="","",INDEX(O1_Community_Attributes!$V$1:$V$500,MATCH($A10,O1_Community_Attributes!$A$1:$A$500,0))),"")) | N10: =IF($A10="","",IFERROR(IF(INDEX(O1_Community_Attributes!$W$1:$W$500,MATCH($A10,O1_Community_Attributes!$A$1:$A$500,0))="","",INDEX(O1_Community_Attributes!$W$1:$W$500,MATCH($A10,O1_Community_Attributes!$A$1:$A$500,0))),"")) | O10: =IF($A10="","",IFERROR(IF(INDEX(O1_Community_Attributes!$X$1:$X$500,MATCH($A10,O1_Community_Attributes!$A$1:$A$500,0))="","",INDEX(O1_Community_Attributes!$X$1:$X$500,MATCH($A10,O1_Community_Attributes!$A$1:$A$500,0))),"")) | P10: =IF($A10="","",IFERROR(IF(INDEX(O1_Community_Attributes!$Y$1:$Y$500,MATCH($A10,O1_Community_Attributes!$A$1:$A$500,0))="","",INDEX(O1_Community_Attributes!$Y$1:$Y$500,MATCH($A10,O1_Community_Attributes!$A$1:$A$500,0))),"")) | Q10: =IF($A10="","",IFERROR(IF(INDEX(O1_Community_Attributes!$Z$1:$Z$500,MATCH($A10,O1_Community_Attributes!$A$1:$A$500,0))="","",INDEX(O1_Community_Attributes!$Z$1:$Z$500,MATCH($A10,O1_Community_Attributes!$A$1:$A$500,0))),"")) | R10: =IF($A10="","",IFERROR(IF(INDEX(O1_Community_Attributes!$BK$1:$BK$500,MATCH($A10,O1_Community_Attributes!$A$1:$A$500,0))="","",INDEX(O1_Community_Attributes!$BK$1:$BK$500,MATCH($A10,O1_Community_Attributes!$A$1:$A$500,0))),"")) | S10: =IF(OR($C10="",$M10=""),"",$M10/$C10) | T10: =IF($C10="","",IF(AND($M10="",$P10=""),"",IF($M10="","B",IF(ABS($S10-1)<=0.3,"A",IF(OR($S10>2,$S10<0.5),"C","B"))))) | AB10: A gap beyond 2x usually means the source quoted the TOTAL HOLDING rather than the worked area.
H11: =IF(C11="","",IF(C11<1,"yes","no")) | I11: =IF(C11="","",IF(C11<2.6,"r75",IF(C11<5.2,"r110",IF(C11<9.9,"r150",IF(C11<19.8,"r210","r300"))))) | M11: =IF($A11="","",IFERROR(IF(INDEX(O1_Community_Attributes!$V$1:$V$500,MATCH($A11,O1_Community_Attributes!$A$1:$A$500,0))="","",INDEX(O1_Community_Attributes!$V$1:$V$500,MATCH($A11,O1_Community_Attributes!$A$1:$A$500,0))),"")) | N11: =IF($A11="","",IFERROR(IF(INDEX(O1_Community_Attributes!$W$1:$W$500,MATCH($A11,O1_Community_Attributes!$A$1:$A$500,0))="","",INDEX(O1_Community_Attributes!$W$1:$W$500,MATCH($A11,O1_Community_Attributes!$A$1:$A$500,0))),"")) | O11: =IF($A11="","",IFERROR(IF(INDEX(O1_Community_Attributes!$X$1:$X$500,MATCH($A11,O1_Community_Attributes!$A$1:$A$500,0))="","",INDEX(O1_Community_Attributes!$X$1:$X$500,MATCH($A11,O1_Community_Attributes!$A$1:$A$500,0))),"")) | P11: =IF($A11="","",IFERROR(IF(INDEX(O1_Community_Attributes!$Y$1:$Y$500,MATCH($A11,O1_Community_Attributes!$A$1:$A$500,0))="","",INDEX(O1_Community_Attributes!$Y$1:$Y$500,MATCH($A11,O1_Community_Attributes!$A$1:$A$500,0))),"")) | Q11: =IF($A11="","",IFERROR(IF(INDEX(O1_Community_Attributes!$Z$1:$Z$500,MATCH($A11,O1_Community_Attributes!$A$1:$A$500,0))="","",INDEX(O1_Community_Attributes!$Z$1:$Z$500,MATCH($A11,O1_Community_Attributes!$A$1:$A$500,0))),"")) | R11: =IF($A11="","",IFERROR(IF(INDEX(O1_Community_Attributes!$BK$1:$BK$500,MATCH($A11,O1_Community_Attributes!$A$1:$A$500,0))="","",INDEX(O1_Community_Attributes!$BK$1:$BK$500,MATCH($A11,O1_Community_Attributes!$A$1:$A$500,0))),"")) | S11: =IF(OR($C11="",$M11=""),"",$M11/$C11) | T11: =IF($C11="","",IF(AND($M11="",$P11=""),"",IF($M11="","B",IF(ABS($S11-1)<=0.3,"A",IF(OR($S11>2,$S11<0.5),"C","B")))))
H12: =IF(C12="","",IF(C12<1,"yes","no")) | I12: =IF(C12="","",IF(C12<2.6,"r75",IF(C12<5.2,"r110",IF(C12<9.9,"r150",IF(C12<19.8,"r210","r300"))))) | M12: =IF($A12="","",IFERROR(IF(INDEX(O1_Community_Attributes!$V$1:$V$500,MATCH($A12,O1_Community_Attributes!$A$1:$A$500,0))="","",INDEX(O1_Community_Attributes!$V$1:$V$500,MATCH($A12,O1_Community_Attributes!$A$1:$A$500,0))),"")) | N12: =IF($A12="","",IFERROR(IF(INDEX(O1_Community_Attributes!$W$1:$W$500,MATCH($A12,O1_Community_Attributes!$A$1:$A$500,0))="","",INDEX(O1_Community_Attributes!$W$1:$W$500,MATCH($A12,O1_Community_Attributes!$A$1:$A$500,0))),"")) | O12: =IF($A12="","",IFERROR(IF(INDEX(O1_Community_Attributes!$X$1:$X$500,MATCH($A12,O1_Community_Attributes!$A$1:$A$500,0))="","",INDEX(O1_Community_Attributes!$X$1:$X$500,MATCH($A12,O1_Community_Attributes!$A$1:$A$500,0))),"")) | P12: =IF($A12="","",IFERROR(IF(INDEX(O1_Community_Attributes!$Y$1:$Y$500,MATCH($A12,O1_Community_Attributes!$A$1:$A$500,0))="","",INDEX(O1_Community_Attributes!$Y$1:$Y$500,MATCH($A12,O1_Community_Attributes!$A$1:$A$500,0))),"")) | Q12: =IF($A12="","",IFERROR(IF(INDEX(O1_Community_Attributes!$Z$1:$Z$500,MATCH($A12,O1_Community_Attributes!$A$1:$A$500,0))="","",INDEX(O1_Community_Attributes!$Z$1:$Z$500,MATCH($A12,O1_Community_Attributes!$A$1:$A$500,0))),"")) | R12: =IF($A12="","",IFERROR(IF(INDEX(O1_Community_Attributes!$BK$1:$BK$500,MATCH($A12,O1_Community_Attributes!$A$1:$A$500,0))="","",INDEX(O1_Community_Attributes!$BK$1:$BK$500,MATCH($A12,O1_Community_Attributes!$A$1:$A$500,0))),"")) | S12: =IF(OR($C12="",$M12=""),"",$M12/$C12) | T12: =IF($C12="","",IF(AND($M12="",$P12=""),"",IF($M12="","B",IF(ABS($S12-1)<=0.3,"A",IF(OR($S12>2,$S12<0.5),"C","B"))))) | AB12: below_minimum_flag, reference_circle, area_ratio and area_agreement_tier all calculate themselves.
H13: =IF(C13="","",IF(C13<1,"yes","no")) | I13: =IF(C13="","",IF(C13<2.6,"r75",IF(C13<5.2,"r110",IF(C13<9.9,"r150",IF(C13<19.8,"r210","r300"))))) | M13: =IF($A13="","",IFERROR(IF(INDEX(O1_Community_Attributes!$V$1:$V$500,MATCH($A13,O1_Community_Attributes!$A$1:$A$500,0))="","",INDEX(O1_Community_Attributes!$V$1:$V$500,MATCH($A13,O1_Community_Attributes!$A$1:$A$500,0))),"")) | N13: =IF($A13="","",IFERROR(IF(INDEX(O1_Community_Attributes!$W$1:$W$500,MATCH($A13,O1_Community_Attributes!$A$1:$A$500,0))="","",INDEX(O1_Community_Attributes!$W$1:$W$500,MATCH($A13,O1_Community_Attributes!$A$1:$A$500,0))),"")) | O13: =IF($A13="","",IFERROR(IF(INDEX(O1_Community_Attributes!$X$1:$X$500,MATCH($A13,O1_Community_Attributes!$A$1:$A$500,0))="","",INDEX(O1_Community_Attributes!$X$1:$X$500,MATCH($A13,O1_Community_Attributes!$A$1:$A$500,0))),"")) | P13: =IF($A13="","",IFERROR(IF(INDEX(O1_Community_Attributes!$Y$1:$Y$500,MATCH($A13,O1_Community_Attributes!$A$1:$A$500,0))="","",INDEX(O1_Community_Attributes!$Y$1:$Y$500,MATCH($A13,O1_Community_Attributes!$A$1:$A$500,0))),"")) | Q13: =IF($A13="","",IFERROR(IF(INDEX(O1_Community_Attributes!$Z$1:$Z$500,MATCH($A13,O1_Community_Attributes!$A$1:$A$500,0))="","",INDEX(O1_Community_Attributes!$Z$1:$Z$500,MATCH($A13,O1_Community_Attributes!$A$1:$A$500,0))),"")) | R13: =IF($A13="","",IFERROR(IF(INDEX(O1_Community_Attributes!$BK$1:$BK$500,MATCH($A13,O1_Community_Attributes!$A$1:$A$500,0))="","",INDEX(O1_Community_Attributes!$BK$1:$BK$500,MATCH($A13,O1_Community_Attributes!$A$1:$A$500,0))),"")) | S13: =IF(OR($C13="",$M13=""),"",$M13/$C13) | T13: =IF($C13="","",IF(AND($M13="",$P13=""),"",IF($M13="","B",IF(ABS($S13-1)<=0.3,"A",IF(OR($S13>2,$S13<0.5),"C","B")))))
H14: =IF(C14="","",IF(C14<1,"yes","no")) | I14: =IF(C14="","",IF(C14<2.6,"r75",IF(C14<5.2,"r110",IF(C14<9.9,"r150",IF(C14<19.8,"r210","r300"))))) | M14: =IF($A14="","",IFERROR(IF(INDEX(O1_Community_Attributes!$V$1:$V$500,MATCH($A14,O1_Community_Attributes!$A$1:$A$500,0))="","",INDEX(O1_Community_Attributes!$V$1:$V$500,MATCH($A14,O1_Community_Attributes!$A$1:$A$500,0))),"")) | N14: =IF($A14="","",IFERROR(IF(INDEX(O1_Community_Attributes!$W$1:$W$500,MATCH($A14,O1_Community_Attributes!$A$1:$A$500,0))="","",INDEX(O1_Community_Attributes!$W$1:$W$500,MATCH($A14,O1_Community_Attributes!$A$1:$A$500,0))),"")) | O14: =IF($A14="","",IFERROR(IF(INDEX(O1_Community_Attributes!$X$1:$X$500,MATCH($A14,O1_Community_Attributes!$A$1:$A$500,0))="","",INDEX(O1_Community_Attributes!$X$1:$X$500,MATCH($A14,O1_Community_Attributes!$A$1:$A$500,0))),"")) | P14: =IF($A14="","",IFERROR(IF(INDEX(O1_Community_Attributes!$Y$1:$Y$500,MATCH($A14,O1_Community_Attributes!$A$1:$A$500,0))="","",INDEX(O1_Community_Attributes!$Y$1:$Y$500,MATCH($A14,O1_Community_Attributes!$A$1:$A$500,0))),"")) | Q14: =IF($A14="","",IFERROR(IF(INDEX(O1_Community_Attributes!$Z$1:$Z$500,MATCH($A14,O1_Community_Attributes!$A$1:$A$500,0))="","",INDEX(O1_Community_Attributes!$Z$1:$Z$500,MATCH($A14,O1_Community_Attributes!$A$1:$A$500,0))),"")) | R14: =IF($A14="","",IFERROR(IF(INDEX(O1_Community_Attributes!$BK$1:$BK$500,MATCH($A14,O1_Community_Attributes!$A$1:$A$500,0))="","",INDEX(O1_Community_Attributes!$BK$1:$BK$500,MATCH($A14,O1_Community_Attributes!$A$1:$A$500,0))),"")) | S14: =IF(OR($C14="",$M14=""),"",$M14/$C14) | T14: =IF($C14="","",IF(AND($M14="",$P14=""),"",IF($M14="","B",IF(ABS($S14-1)<=0.3,"A",IF(OR($S14>2,$S14<0.5),"C","B"))))) | AB14: NEW IN v6 — columns M to R READ THEMSELVES FROM O1_Community_Attributes and must not be typed into. Paste the register's Block E into O1; it arrives here on its own.
H15: =IF(C15="","",IF(C15<1,"yes","no")) | I15: =IF(C15="","",IF(C15<2.6,"r75",IF(C15<5.2,"r110",IF(C15<9.9,"r150",IF(C15<19.8,"r210","r300"))))) | M15: =IF($A15="","",IFERROR(IF(INDEX(O1_Community_Attributes!$V$1:$V$500,MATCH($A15,O1_Community_Attributes!$A$1:$A$500,0))="","",INDEX(O1_Community_Attributes!$V$1:$V$500,MATCH($A15,O1_Community_Attributes!$A$1:$A$500,0))),"")) | N15: =IF($A15="","",IFERROR(IF(INDEX(O1_Community_Attributes!$W$1:$W$500,MATCH($A15,O1_Community_Attributes!$A$1:$A$500,0))="","",INDEX(O1_Community_Attributes!$W$1:$W$500,MATCH($A15,O1_Community_Attributes!$A$1:$A$500,0))),"")) | O15: =IF($A15="","",IFERROR(IF(INDEX(O1_Community_Attributes!$X$1:$X$500,MATCH($A15,O1_Community_Attributes!$A$1:$A$500,0))="","",INDEX(O1_Community_Attributes!$X$1:$X$500,MATCH($A15,O1_Community_Attributes!$A$1:$A$500,0))),"")) | P15: =IF($A15="","",IFERROR(IF(INDEX(O1_Community_Attributes!$Y$1:$Y$500,MATCH($A15,O1_Community_Attributes!$A$1:$A$500,0))="","",INDEX(O1_Community_Attributes!$Y$1:$Y$500,MATCH($A15,O1_Community_Attributes!$A$1:$A$500,0))),"")) | Q15: =IF($A15="","",IFERROR(IF(INDEX(O1_Community_Attributes!$Z$1:$Z$500,MATCH($A15,O1_Community_Attributes!$A$1:$A$500,0))="","",INDEX(O1_Community_Attributes!$Z$1:$Z$500,MATCH($A15,O1_Community_Attributes!$A$1:$A$500,0))),"")) | R15: =IF($A15="","",IFERROR(IF(INDEX(O1_Community_Attributes!$BK$1:$BK$500,MATCH($A15,O1_Community_Attributes!$A$1:$A$500,0))="","",INDEX(O1_Community_Attributes!$BK$1:$BK$500,MATCH($A15,O1_Community_Attributes!$A$1:$A$500,0))),"")) | S15: =IF(OR($C15="",$M15=""),"",$M15/$C15) | T15: =IF($C15="","",IF(AND($M15="",$P15=""),"",IF($M15="","B",IF(ABS($S15-1)<=0.3,"A",IF(OR($S15>2,$S15<0.5),"C","B"))))) | AB15: NEW IN v6 — a site with a polygon but NO documentary figure is tier B, per plan 7.1a. In v5 it was left blank, which looked identical to a site not yet coded.
H16: =IF(C16="","",IF(C16<1,"yes","no")) | I16: =IF(C16="","",IF(C16<2.6,"r75",IF(C16<5.2,"r110",IF(C16<9.9,"r150",IF(C16<19.8,"r210","r300"))))) | M16: =IF($A16="","",IFERROR(IF(INDEX(O1_Community_Attributes!$V$1:$V$500,MATCH($A16,O1_Community_Attributes!$A$1:$A$500,0))="","",INDEX(O1_Community_Attributes!$V$1:$V$500,MATCH($A16,O1_Community_Attributes!$A$1:$A$500,0))),"")) | N16: =IF($A16="","",IFERROR(IF(INDEX(O1_Community_Attributes!$W$1:$W$500,MATCH($A16,O1_Community_Attributes!$A$1:$A$500,0))="","",INDEX(O1_Community_Attributes!$W$1:$W$500,MATCH($A16,O1_Community_Attributes!$A$1:$A$500,0))),"")) | O16: =IF($A16="","",IFERROR(IF(INDEX(O1_Community_Attributes!$X$1:$X$500,MATCH($A16,O1_Community_Attributes!$A$1:$A$500,0))="","",INDEX(O1_Community_Attributes!$X$1:$X$500,MATCH($A16,O1_Community_Attributes!$A$1:$A$500,0))),"")) | P16: =IF($A16="","",IFERROR(IF(INDEX(O1_Community_Attributes!$Y$1:$Y$500,MATCH($A16,O1_Community_Attributes!$A$1:$A$500,0))="","",INDEX(O1_Community_Attributes!$Y$1:$Y$500,MATCH($A16,O1_Community_Attributes!$A$1:$A$500,0))),"")) | Q16: =IF($A16="","",IFERROR(IF(INDEX(O1_Community_Attributes!$Z$1:$Z$500,MATCH($A16,O1_Community_Attributes!$A$1:$A$500,0))="","",INDEX(O1_Community_Attributes!$Z$1:$Z$500,MATCH($A16,O1_Community_Attributes!$A$1:$A$500,0))),"")) | R16: =IF($A16="","",IFERROR(IF(INDEX(O1_Community_Attributes!$BK$1:$BK$500,MATCH($A16,O1_Community_Attributes!$A$1:$A$500,0))="","",INDEX(O1_Community_Attributes!$BK$1:$BK$500,MATCH($A16,O1_Community_Attributes!$A$1:$A$500,0))),"")) | S16: =IF(OR($C16="",$M16=""),"",$M16/$C16) | T16: =IF($C16="","",IF(AND($M16="",$P16=""),"",IF($M16="","B",IF(ABS($S16-1)<=0.3,"A",IF(OR($S16>2,$S16<0.5),"C","B")))))
H17: =IF(C17="","",IF(C17<1,"yes","no")) | I17: =IF(C17="","",IF(C17<2.6,"r75",IF(C17<5.2,"r110",IF(C17<9.9,"r150",IF(C17<19.8,"r210","r300"))))) | M17: =IF($A17="","",IFERROR(IF(INDEX(O1_Community_Attributes!$V$1:$V$500,MATCH($A17,O1_Community_Attributes!$A$1:$A$500,0))="","",INDEX(O1_Community_Attributes!$V$1:$V$500,MATCH($A17,O1_Community_Attributes!$A$1:$A$500,0))),"")) | N17: =IF($A17="","",IFERROR(IF(INDEX(O1_Community_Attributes!$W$1:$W$500,MATCH($A17,O1_Community_Attributes!$A$1:$A$500,0))="","",INDEX(O1_Community_Attributes!$W$1:$W$500,MATCH($A17,O1_Community_Attributes!$A$1:$A$500,0))),"")) | O17: =IF($A17="","",IFERROR(IF(INDEX(O1_Community_Attributes!$X$1:$X$500,MATCH($A17,O1_Community_Attributes!$A$1:$A$500,0))="","",INDEX(O1_Community_Attributes!$X$1:$X$500,MATCH($A17,O1_Community_Attributes!$A$1:$A$500,0))),"")) | P17: =IF($A17="","",IFERROR(IF(INDEX(O1_Community_Attributes!$Y$1:$Y$500,MATCH($A17,O1_Community_Attributes!$A$1:$A$500,0))="","",INDEX(O1_Community_Attributes!$Y$1:$Y$500,MATCH($A17,O1_Community_Attributes!$A$1:$A$500,0))),"")) | Q17: =IF($A17="","",IFERROR(IF(INDEX(O1_Community_Attributes!$Z$1:$Z$500,MATCH($A17,O1_Community_Attributes!$A$1:$A$500,0))="","",INDEX(O1_Community_Attributes!$Z$1:$Z$500,MATCH($A17,O1_Community_Attributes!$A$1:$A$500,0))),"")) | R17: =IF($A17="","",IFERROR(IF(INDEX(O1_Community_Attributes!$BK$1:$BK$500,MATCH($A17,O1_Community_Attributes!$A$1:$A$500,0))="","",INDEX(O1_Community_Attributes!$BK$1:$BK$500,MATCH($A17,O1_Community_Attributes!$A$1:$A$500,0))),"")) | S17: =IF(OR($C17="",$M17=""),"",$M17/$C17) | T17: =IF($C17="","",IF(AND($M17="",$P17=""),"",IF($M17="","B",IF(ABS($S17-1)<=0.3,"A",IF(OR($S17>2,$S17<0.5),"C","B")))))
H18: =IF(C18="","",IF(C18<1,"yes","no")) | I18: =IF(C18="","",IF(C18<2.6,"r75",IF(C18<5.2,"r110",IF(C18<9.9,"r150",IF(C18<19.8,"r210","r300"))))) | M18: =IF($A18="","",IFERROR(IF(INDEX(O1_Community_Attributes!$V$1:$V$500,MATCH($A18,O1_Community_Attributes!$A$1:$A$500,0))="","",INDEX(O1_Community_Attributes!$V$1:$V$500,MATCH($A18,O1_Community_Attributes!$A$1:$A$500,0))),"")) | N18: =IF($A18="","",IFERROR(IF(INDEX(O1_Community_Attributes!$W$1:$W$500,MATCH($A18,O1_Community_Attributes!$A$1:$A$500,0))="","",INDEX(O1_Community_Attributes!$W$1:$W$500,MATCH($A18,O1_Community_Attributes!$A$1:$A$500,0))),"")) | O18: =IF($A18="","",IFERROR(IF(INDEX(O1_Community_Attributes!$X$1:$X$500,MATCH($A18,O1_Community_Attributes!$A$1:$A$500,0))="","",INDEX(O1_Community_Attributes!$X$1:$X$500,MATCH($A18,O1_Community_Attributes!$A$1:$A$500,0))),"")) | P18: =IF($A18="","",IFERROR(IF(INDEX(O1_Community_Attributes!$Y$1:$Y$500,MATCH($A18,O1_Community_Attributes!$A$1:$A$500,0))="","",INDEX(O1_Community_Attributes!$Y$1:$Y$500,MATCH($A18,O1_Community_Attributes!$A$1:$A$500,0))),"")) | Q18: =IF($A18="","",IFERROR(IF(INDEX(O1_Community_Attributes!$Z$1:$Z$500,MATCH($A18,O1_Community_Attributes!$A$1:$A$500,0))="","",INDEX(O1_Community_Attributes!$Z$1:$Z$500,MATCH($A18,O1_Community_Attributes!$A$1:$A$500,0))),"")) | R18: =IF($A18="","",IFERROR(IF(INDEX(O1_Community_Attributes!$BK$1:$BK$500,MATCH($A18,O1_Community_Attributes!$A$1:$A$500,0))="","",INDEX(O1_Community_Attributes!$BK$1:$BK$500,MATCH($A18,O1_Community_Attributes!$A$1:$A$500,0))),"")) | S18: =IF(OR($C18="",$M18=""),"",$M18/$C18) | T18: =IF($C18="","",IF(AND($M18="",$P18=""),"",IF($M18="","B",IF(ABS($S18-1)<=0.3,"A",IF(OR($S18>2,$S18<0.5),"C","B")))))
