Workbook

Sheet README
A1: STAGE 1 — ESSENTIAL DATA WORKBOOK
A2: Version 1.0 · aligned to THE_SIMPLIFIED_PLAN_v4.0 and WEB_SEARCH_FIELD_REGISTER_AND_CHATGPT_PROMPT_v3.0
A4: WHAT THIS WORKBOOK IS
A5: Purpose | B5: Stage 1 produces two things: the ESSENTIAL DOCUMENTARY DATA the rest of the study consumes, and the MEASUREMENT GEOMETRY the whole study is measured over. Nothing else. Every column here has a named downstream consumer in the plan; a column with no consumer was deleted rather than kept for completeness.
A6: What it replaces | B6: Stage_1_Documentary_Coding_Workbook_v6. That workbook is preserved unchanged. This one is rebuilt from scratch, not edited: the practice-code sheets are absent rather than hidden, and no practice column, dropdown, formula or named range survives anywhere in this file.
A7: What was removed and why | B7: Documentary practice codes (the thirteen pc* codes), the practice matrix, the practice evidence sheet and the claim-to-signature map are gone. Practice-level documentary information could not be established with sufficient completeness, consistency or independent verification across 212 communities to support quantitative inference. See DECISION_MEMO.md.
A9: THE ONE RULE
A10: You are recording what sources SAY | B10: You are documenting what communities say, what independent sources say, and what can be established historically. You are NOT assessing ecological performance — the satellite pipeline does that, later, and it must not be influenced by anything here.
A11: Blindness | B11: Do not view satellite metrics, index values or any outcome data while coding or drawing. Historical high-resolution imagery is permitted and required for the polygon; derived vegetation quantities are not.
A12: Boundary with Stage 2 | B12: Stage 1 produces coded facts. Stage 2 consumes them to build the matched control sample. Never record an eligibility decision here that Stage 2 should be making.
A14: SHEETS, AND WHAT EACH OWNS
A15: Community_Register | B15: OWNS identity, eligibility, population, the documentary area figures, the five evidence channels, status, context and crawl provenance.
A16: Onset_Register | B16: OWNS every onset field and cohort candidacy. The priority block.
A17: Polygon_Geometry | B17: OWNS the drawn polygon and its reliability. READS the documentary area from Community_Register to compute the agreement tier.
A18: Source_Index | B18: One row per source, with its independence group and a mandatory verified_resolves check.
A19: Source_Set | B19: One row per web address per community.
A20: Search_Log | B20: One row per database per community, INCLUDING those that returned nothing. This is where 'evidence absent' is separated from 'not looked for'.
A21: Disagreement_Log | B21: Every double-coding disagreement and how it was resolved.
A22: Reliability_Report | B22: Agreement per variable. Pre-filled with the fourteen variables the plan requires.
A23: Enquiry_Record | B23: Only if you contact communities. Consent and ethics reference.
A24: Definitions_And_Freeze | B24: The definitions and agreement thresholds for every judgement-bearing variable, with ONE freeze date. Replaces the practice codebook.
A25: Calibration | B25: A coder proceeds to production only after meeting the threshold.
A26: Decision_Log | B26: Appendix A of the plan. One row per decision, with a date.
... A28: Reference_Codes | B28: The full vocabulary with the rule behind each value, and the list of quantities that must NEVER be searched for.
A30: HOW TO USE IT
A31: Dark header row | B31: Every sheet has one, with an auto-filter. Type beneath it.
A32: Pale blue cells | B32: Computed. They contain formulas. Do not type into them — a typed value there is a second authoritative entry point and the two will drift.
A33: Yellow cells | B33: You must fill them: the freeze date on Definitions_And_Freeze.
A34: Dropdowns | B34: Every controlled-vocabulary column has one. Use it. 'Evidenced' and 'evidenced' are different strings and will corrupt every count.
A35: No example rows | B35: Row 2 is empty and ready. The format is in Reference_Codes and in Definitions_And_Freeze, so there is no example row to forget to delete.
A37: SEQUENCE — do not start at IC001
A38: 1 Freeze | B38: Complete Definitions_And_Freeze, confirm every agreement threshold, and enter the freeze date. After that date the definitions may not change; a later change means the affected variable is re-coded IN FULL.
A39: 2 Design | B39: Draw the 20 per cent double-coding subsample with a recorded seed, stratified by region and expected evidence tier. Record the seed in Decision_Log.
A40: 3 Calibrate | B40: Train on communities NOT in the study sample. Record in Calibration. Proceed only after meeting the declared threshold.
A41: 4 Code | B41: Fill Source_Set for a community before coding it, so you know what you are working from. Then Community_Register and Onset_Register.
A42: 5 Draw | B42: Draw the polygon at every settlement, from STRUCTURE and never from colour. Translate it onto all three controls. Record in Polygon_Geometry.
A43: 6 Decide | B43: At community 100, read Cohort_Tracker and make decision D4.
A44: 7 Close | B44: Re-code the 20 per cent after at least four weeks. Compute reliability PER VARIABLE. Freeze and version the dataset.
A46: SEVEN RULES MOST OFTEN BROKEN
A47: Founding year is not onset | B47: A community founded in 1985 that began ecological work in 1992 has an onset of 1992. Record both.
...

Sheet Cohort_Tracker
A1: LONGITUDINAL COHORT TRACKER — decision D4
A2: Analysis A7 needs about 65 communities with onset in 2020 or 2021. Decide at community 100, not at the end.
A3: Quantity | B3: Value | C3: What it means
A4: Communities coded so far | B4: =COUNTA(Community_Register!A2:A402) | C4: Decision D4 is taken at 100.
A5: cohort_candidate = core (2020-2021) | B5: =COUNTIF(Onset_Register!Q2:Q402,"core (2020-2021)") | C5: The pool of candidates.
A6: of those, confidence tier A or B | B6: =COUNTIFS(Onset_Register!Q2:Q402,"core (2020-2021)",Onset_Register!O2:O402,"A")+COUNTIFS(Onset_Register!Q2:Q402,"core (2020-2021)",Onset_Register!O2:O402,"B") | C6: THE NUMBER THAT MATTERS. Tier C onsets are too uncertain to anchor a before-and-after window.
A7: cohort_candidate = extension (2019) | B7: =COUNTIF(Onset_Register!Q2:Q402,"extension (2019)") | C7: Usable if the core falls short — costs one pre-onset year.
A8: cohort_candidate = uncertain | B8: =COUNTIF(Onset_Register!Q2:Q402,"uncertain") | C8: Resolve these before deciding.
A9: DECISION D4 STATUS | B9: =IF(COUNTA(Community_Register!A2:A402)<100,"KEEP CODING — decide at community 100",IF($B$6>=50,"PROCEED — the component is well worth its four to six weeks",IF($B$6>=40,"PROCEED BUT REPORT AS EXPLORATORY","DROP THE COMPONENT — an underpowered before-and-after test does more harm than omitting it"))) | C9: Thresholds from the plan: counted on core AND tier A or B. Above 50 proceed; 40 to 50 proceed but report as exploratory; below 40 drop the component.

Sheet Community_Register
A1: site_id | B1: community_name_official | C1: alternative_names | D1: country | E1: admin_region | F1: latitude | G1: longitude | H1: coordinate_agreement | I1: e1_network_listing | J1: e1_pathway | K1: e1_self_identification | L1: e2_settlement_type | M1: e2_evidence_note | N1: e8_setting_at_onset | O1: population_value | P1: population_lower | Q1: population_upper | R1: population_source_date | S1: managed_area_ha | T1: managed_area_lower_ha | U1: managed_area_upper_ha | V1: managed_area_basis | W1: managed_area_source_class | X1: documentary_area_note | Y1: total_holding_ha | Z1: area_type | AA1: parcel_structure | AB1: v1_self_documentation | AC1: v2_external_documentation | AD1: v3_substantive_affiliation | AE1: v4_visual_documentation | AF1: v5_continuity_evidence | AG1: channel_count | AH1: evidence_tier | AI1: status_current | AJ1: status_evidence | AK1: last_listing_year | AL1: dissolution_year | AM1: delisting_reason | AN1: external_funding_or_programme | AO1: protected_area_status | AP1: notable_context | AQ1: pages_opened_count | AR1: documents_opened | AS1: source_classes_found | AT1: search_languages | AU1: negative_consultations | AV1: independence_groups | AW1: stages_completed | AX1: crawl_truncated | AY1: coder_id | AZ1: coding_date | BA1: double_coded | BB1: second_coder_id | BC1: notes | BE1: ONE ROW PER COMMUNITY. THE SINGLE PASTE TARGET.
AG2: =IF(COUNTA(AB2:AF2)=0,"",COUNTIF(AB2:AF2,"yes")) | AH2: =IF($AG2="","",IF($AG2<2,"Fail",IF(OR($AC2="yes",$AD2="yes"),IF($AG2>=3,"A","B"),"C"))) | BE2: Field names are identical to the web-search register v3.0, so a returned record pastes straight in.
AG3: =IF(COUNTA(AB3:AF3)=0,"",COUNTIF(AB3:AF3,"yes")) | AH3: =IF($AG3="","",IF($AG3<2,"Fail",IF(OR($AC3="yes",$AD3="yes"),IF($AG3>=3,"A","B"),"C")))
AG4: =IF(COUNTA(AB4:AF4)=0,"",COUNTIF(AB4:AF4,"yes")) | AH4: =IF($AG4="","",IF($AG4<2,"Fail",IF(OR($AC4="yes",$AD4="yes"),IF($AG4>=3,"A","B"),"C"))) | BE4: channel_count and evidence_tier are COMPUTED from v1..v5. Do not type them. In v6 they were typed and could disagree with the channels behind them.
AG5: =IF(COUNTA(AB5:AF5)=0,"",COUNTIF(AB5:AF5,"yes")) | AH5: =IF($AG5="","",IF($AG5<2,"Fail",IF(OR($AC5="yes",$AD5="yes"),IF($AG5>=3,"A","B"),"C")))
AG6: =IF(COUNTA(AB6:AF6)=0,"",COUNTIF(AB6:AF6,"yes")) | AH6: =IF($AG6="","",IF($AG6<2,"Fail",IF(OR($AC6="yes",$AD6="yes"),IF($AG6>=3,"A","B"),"C"))) | BE6: evidence_tier is an EVIDENCE-QUALITY variable. It records how well documented a community's ecological work is, not how much of it there is. It is used as a named confounder in analysis A4, as a sample-description variable, and behind sensitivity check SC18. It must never be reported as an ecological-performance measure, and it must never be disaggregated by KIND of activity — doing that would rebuild a practice score by another name.
AG7: =IF(COUNTA(AB7:AF7)=0,"",COUNTIF(AB7:AF7,"yes")) | AH7: =IF($AG7="","",IF($AG7<2,"Fail",IF(OR($AC7="yes",$AD7="yes"),IF($AG7>=3,"A","B"),"C")))
AG8: =IF(COUNTA(AB8:AF8)=0,"",COUNTIF(AB8:AF8,"yes")) | AH8: =IF($AG8="","",IF($AG8<2,"Fail",IF(OR($AC8="yes",$AD8="yes"),IF($AG8>=3,"A","B"),"C"))) | BE8: The tier rule, ordered by INDEPENDENCE and then by amount: Fail = fewer than two channels; C = two or more channels but NO external one (V2, V3); B = an external channel and two channels in total; A = an external channel and three or more. v2.4 ordered by count first, which made its tier C unreachable and ranked three self-documented channels above two including a thesis.
AG9: =IF(COUNTA(AB9:AF9)=0,"",COUNTIF(AB9:AF9,"yes")) | AH9: =IF($AG9="","",IF($AG9<2,"Fail",IF(OR($AC9="yes",$AD9="yes"),IF($AG9>=3,"A","B"),"C")))
AG10: =IF(COUNTA(AB10:AF10)=0,"",COUNTIF(AB10:AF10,"yes")) | AH10: =IF($AG10="","",IF($AG10<2,"Fail",IF(OR($AC10="yes",$AD10="yes"),IF($AG10>=3,"A","B"),"C"))) | BE10: managed_area_ha is the worked area, NEVER the total holding. Both are recorded separately. Polygon_Geometry reads managed_area_ha from column S of this sheet to compute the agreement tier; it is entered here and nowhere else.
AG11: =IF(COUNTA(AB11:AF11)=0,"",COUNTIF(AB11:AF11,"yes")) | AH11: =IF($AG11="","",IF($AG11<2,"Fail",IF(OR($AC11="yes",$AD11="yes"),IF($AG11>=3,"A","B"),"C")))
AG12: =IF(COUNTA(AB12:AF12)=0,"",COUNTIF(AB12:AF12,"yes")) | AH12: =IF($AG12="","",IF($AG12<2,"Fail",IF(OR($AC12="yes",$AD12="yes"),IF($AG12>=3,"A","B"),"C"))) | BE12: population_value appears once. In v2.4 of the register the same quantity was collected twice, as e3_population_value and population_value, which is two authoritative entry points for one number.
AG13: =IF(COUNTA(AB13:AF13)=0,"",COUNTIF(AB13:AF13,"yes")) | AH13: =IF($AG13="","",IF($AG13<2,"Fail",IF(OR($AC13="yes",$AD13="yes"),IF($AG13>=3,"A","B"),"C")))
AG14: =IF(COUNTA(AB14:AF14)=0,"",COUNTIF(AB14:AF14,"yes")) | AH14: =IF($AG14="","",IF($AG14<2,"Fail",IF(OR($AC14="yes",$AD14="yes"),IF($AG14>=3,"A","B"),"C"))) | BE14: crawl_truncated = yes is not a failure. A truncated run that says so is useful data; a truncated run that reads as a complete one is worse than no run at all.
AG15: =IF(COUNTA(AB15:AF15)=0,"",COUNTIF(AB15:AF15,"yes")) | AH15: =IF($AG15="","",IF($AG15<2,"Fail",IF(OR($AC15="yes",$AD15="yes"),IF($AG15>=3,"A","B"),"C")))
AG16: =IF(COUNTA(AB16:AF16)=0,"",COUNTIF(AB16:AF16,"yes")) | AH16: =IF($AG16="","",IF($AG16<2,"Fail",IF(OR($AC16="yes",$AD16="yes"),IF($AG16>=3,"A","B"),"C")))
AG17: =IF(COUNTA(AB17:AF17)=0,"",COUNTIF(AB17:AF17,"yes")) | AH17: =IF($AG17="","",IF($AG17<2,"Fail",IF(OR($AC17="yes",$AD17="yes"),IF($AG17>=3,"A","B"),"C")))
AG18: =IF(COUNTA(AB18:AF18)=0,"",COUNTIF(AB18:AF18,"yes")) | AH18: =IF($AG18="","",IF($AG18<2,"Fail",IF(OR($AC18="yes",$AD18="yes"),IF($AG18>=3,"A","B"),"C")))
AG19: =IF(COUNTA(AB19:AF19)=0,"",COUNTIF(AB19:AF19,"yes")) | AH19: =IF($AG19="","",IF($AG19<2,"Fail",IF(OR($AC19="yes",$AD19="yes"),IF($AG19>=3,"A","B"),"C")))
AG20: =IF(COUNTA(AB20:AF20)=0,"",COUNTIF(AB20:AF20,"yes")) | AH20: =IF($AG20="","",IF($AG20<2,"Fail",IF(OR($AC20="yes",$AD20="yes"),IF($AG20>=3,"A","B"),"C")))
AG21: =IF(COUNTA(AB21:AF21)=0,"",COUNTIF(AB21:AF21,"yes")) | AH21: =IF($AG21="","",IF($AG21<2,"Fail",IF(OR($AC21="yes",$AD21="yes"),IF($AG21>=3,"A","B"),"C")))
AG22: =IF(COUNTA(AB22:AF22)=0,"",COUNTIF(AB22:AF22,"yes")) | AH22: =IF($AG22="","",IF($AG22<2,"Fail",IF(OR($AC22="yes",$AD22="yes"),IF($AG22>=3,"A","B"),"C")))
AG23: =IF(COUNTA(AB23:AF23)=0,"",COUNTIF(AB23:AF23,"yes")) | AH23: =IF($AG23="","",IF($AG23<2,"Fail",IF(OR($AC23="yes",$AD23="yes"),IF($AG23>=3,"A","B"),"C")))
AG24: =IF(COUNTA(AB24:AF24)=0,"",COUNTIF(AB24:AF24,"yes")) | AH24: =IF($AG24="","",IF($AG24<2,"Fail",IF(OR($AC24="yes",$AD24="yes"),IF($AG24>=3,"A","B"),"C")))
AG25: =IF(COUNTA(AB25:AF25)=0,"",COUNTIF(AB25:AF25,"yes")) | AH25: =IF($AG25="","",IF($AG25<2,"Fail",IF(OR($AC25="yes",$AD25="yes"),IF($AG25>=3,"A","B"),"C")))
AG26: =IF(COUNTA(AB26:AF26)=0,"",COUNTIF(AB26:AF26,"yes")) | AH26: =IF($AG26="","",IF($AG26<2,"Fail",IF(OR($AC26="yes",$AD26="yes"),IF($AG26>=3,"A","B"),"C")))
... AG402: =IF(COUNTA(AB402:AF402)=0,"",COUNTIF(AB402:AF402,"yes")) | AH402: =IF($AG402="","",IF($AG402<2,"Fail",IF(OR($AC402="yes",$AD402="yes"),IF($AG402>=3,"A","B"),"C")))

Sheet Onset_Register
A1: site_id | B1: community_name | C1: date_formal_founding | D1: founding_decade | E1: date_land_acquisition | F1: date_intervention_onset | G1: onset_lower_bound | H1: onset_upper_bound | I1: onset_band_width_years | J1: onset_evidence_rank | K1: onset_evidence_description | L1: onset_conflicting_sources | M1: resolution_rule | N1: onset_proxy_flag | O1: onset_confidence_tier | P1: onset_first_or_major | Q1: cohort_candidate | R1: source_ids | S1: coder_id | T1: coding_date | U1: notes | W1: THE PRIORITY BLOCK. More analyses depend on onset than on any other documentary field, and it is the hardest field to establish.
B2: =IF($A2="","",IFERROR(IF(INDEX(Community_Register!$B$2:$B$402,MATCH($A2,Community_Register!$A$2:$A$402,0))="","",INDEX(Community_Register!$B$2:$B$402,MATCH($A2,Community_Register!$A$2:$A$402,0))),"")) | D2: =IF(OR($C2="",NOT(ISNUMBER($C2))),"",FLOOR($C2,10)) | I2: =IF(OR($G2="",$H2="",NOT(ISNUMBER($G2)),NOT(ISNUMBER($H2))),"",$H2-$G2)
B3: =IF($A3="","",IFERROR(IF(INDEX(Community_Register!$B$2:$B$402,MATCH($A3,Community_Register!$A$2:$A$402,0))="","",INDEX(Community_Register!$B$2:$B$402,MATCH($A3,Community_Register!$A$2:$A$402,0))),"")) | D3: =IF(OR($C3="",NOT(ISNUMBER($C3))),"",FLOOR($C3,10)) | I3: =IF(OR($G3="",$H3="",NOT(ISNUMBER($G3)),NOT(ISNUMBER($H3))),"",$H3-$G3) | W3: Three candidate dates are retained and only ONE of them is the study's onset. date_formal_founding distinguishes founding from onset — the study's central dating rule. date_land_acquisition is the hardest available LOWER bound: a community cannot intervene on land it does not hold. date_intervention_onset is the onset.
B4: =IF($A4="","",IFERROR(IF(INDEX(Community_Register!$B$2:$B$402,MATCH($A4,Community_Register!$A$2:$A$402,0))="","",INDEX(Community_Register!$B$2:$B$402,MATCH($A4,Community_Register!$A$2:$A$402,0))),"")) | D4: =IF(OR($C4="",NOT(ISNUMBER($C4))),"",FLOOR($C4,10)) | I4: =IF(OR($G4="",$H4="",NOT(ISNUMBER($G4)),NOT(ISNUMBER($H4))),"",$H4-$G4)
B5: =IF($A5="","",IFERROR(IF(INDEX(Community_Register!$B$2:$B$402,MATCH($A5,Community_Register!$A$2:$A$402,0))="","",INDEX(Community_Register!$B$2:$B$402,MATCH($A5,Community_Register!$A$2:$A$402,0))),"")) | D5: =IF(OR($C5="",NOT(ISNUMBER($C5))),"",FLOOR($C5,10)) | I5: =IF(OR($G5="",$H5="",NOT(ISNUMBER($G5)),NOT(ISNUMBER($H5))),"",$H5-$G5) | W5: date_first_residence and domain_onsets were dropped in v4.0. Neither had a downstream consumer: habitation neither bounds nor dates the intervention, and with practice codes removed there is no per-domain analysis for a per-domain onset to feed. The onset is the EARLIEST deliberate ecological intervention of any kind.
B6: =IF($A6="","",IFERROR(IF(INDEX(Community_Register!$B$2:$B$402,MATCH($A6,Community_Register!$A$2:$A$402,0))="","",INDEX(Community_Register!$B$2:$B$402,MATCH($A6,Community_Register!$A$2:$A$402,0))),"")) | D6: =IF(OR($C6="",NOT(ISNUMBER($C6))),"",FLOOR($C6,10)) | I6: =IF(OR($G6="",$H6="",NOT(ISNUMBER($G6)),NOT(ISNUMBER($H6))),"",$H6-$G6)
B7: =IF($A7="","",IFERROR(IF(INDEX(Community_Register!$B$2:$B$402,MATCH($A7,Community_Register!$A$2:$A$402,0))="","",INDEX(Community_Register!$B$2:$B$402,MATCH($A7,Community_Register!$A$2:$A$402,0))),"")) | D7: =IF(OR($C7="",NOT(ISNUMBER($C7))),"",FLOOR($C7,10)) | I7: =IF(OR($G7="",$H7="",NOT(ISNUMBER($G7)),NOT(ISNUMBER($H7))),"",$H7-$G7) | W7: Where sources of equal rank disagree, take the EARLIER year as the value and let the gap become the lower and upper bounds. Record the disagreement in onset_conflicting_sources whatever you do with it, and the rule you applied in resolution_rule. A conflict is never resolved silently.
B8: =IF($A8="","",IFERROR(IF(INDEX(Community_Register!$B$2:$B$402,MATCH($A8,Community_Register!$A$2:$A$402,0))="","",INDEX(Community_Register!$B$2:$B$402,MATCH($A8,Community_Register!$A$2:$A$402,0))),"")) | D8: =IF(OR($C8="",NOT(ISNUMBER($C8))),"",FLOOR($C8,10)) | I8: =IF(OR($G8="",$H8="",NOT(ISNUMBER($G8)),NOT(ISNUMBER($H8))),"",$H8-$G8)
B9: =IF($A9="","",IFERROR(IF(INDEX(Community_Register!$B$2:$B$402,MATCH($A9,Community_Register!$A$2:$A$402,0))="","",INDEX(Community_Register!$B$2:$B$402,MATCH($A9,Community_Register!$A$2:$A$402,0))),"")) | D9: =IF(OR($C9="",NOT(ISNUMBER($C9))),"",FLOOR($C9,10)) | I9: =IF(OR($G9="",$H9="",NOT(ISNUMBER($G9)),NOT(ISNUMBER($H9))),"",$H9-$G9) | W9: onset_proxy_flag = yes means a founding year was used as a substitute. Those sites leave analysis A4 and stay in every other analysis.
B10: =IF($A10="","",IFERROR(IF(INDEX(Community_Register!$B$2:$B$402,MATCH($A10,Community_Register!$A$2:$A$402,0))="","",INDEX(Community_Register!$B$2:$B$402,MATCH($A10,Community_Register!$A$2:$A$402,0))),"")) | D10: =IF(OR($C10="",NOT(ISNUMBER($C10))),"",FLOOR($C10,10)) | I10: =IF(OR($G10="",$H10="",NOT(ISNUMBER($G10)),NOT(ISNUMBER($H10))),"",$H10-$G10)
B11: =IF($A11="","",IFERROR(IF(INDEX(Community_Register!$B$2:$B$402,MATCH($A11,Community_Register!$A$2:$A$402,0))="","",INDEX(Community_Register!$B$2:$B$402,MATCH($A11,Community_Register!$A$2:$A$402,0))),"")) | D11: =IF(OR($C11="",NOT(ISNUMBER($C11))),"",FLOOR($C11,10)) | I11: =IF(OR($G11="",$H11="",NOT(ISNUMBER($G11)),NOT(ISNUMBER($H11))),"",$H11-$G11) | W11: onset_confidence_tier gates cohort admission: A7 admits tier A and B only.
B12: =IF($A12="","",IFERROR(IF(INDEX(Community_Register!$B$2:$B$402,MATCH($A12,Community_Register!$A$2:$A$402,0))="","",INDEX(Community_Register!$B$2:$B$402,MATCH($A12,Community_Register!$A$2:$A$402,0))),"")) | D12: =IF(OR($C12="",NOT(ISNUMBER($C12))),"",FLOOR($C12,10)) | I12: =IF(OR($G12="",$H12="",NOT(ISNUMBER($G12)),NOT(ISNUMBER($H12))),"",$H12-$G12)
B13: =IF($A13="","",IFERROR(IF(INDEX(Community_Register!$B$2:$B$402,MATCH($A13,Community_Register!$A$2:$A$402,0))="","",INDEX(Community_Register!$B$2:$B$402,MATCH($A13,Community_Register!$A$2:$A$402,0))),"")) | D13: =IF(OR($C13="",NOT(ISNUMBER($C13))),"",FLOOR($C13,10)) | I13: =IF(OR($G13="",$H13="",NOT(ISNUMBER($G13)),NOT(ISNUMBER($H13))),"",$H13-$G13)
B14: =IF($A14="","",IFERROR(IF(INDEX(Community_Register!$B$2:$B$402,MATCH($A14,Community_Register!$A$2:$A$402,0))="","",INDEX(Community_Register!$B$2:$B$402,MATCH($A14,Community_Register!$A$2:$A$402,0))),"")) | D14: =IF(OR($C14="",NOT(ISNUMBER($C14))),"",FLOOR($C14,10)) | I14: =IF(OR($G14="",$H14="",NOT(ISNUMBER($G14)),NOT(ISNUMBER($H14))),"",$H14-$G14)
B15: =IF($A15="","",IFERROR(IF(INDEX(Community_Register!$B$2:$B$402,MATCH($A15,Community_Register!$A$2:$A$402,0))="","",INDEX(Community_Register!$B$2:$B$402,MATCH($A15,Community_Register!$A$2:$A$402,0))),"")) | D15: =IF(OR($C15="",NOT(ISNUMBER($C15))),"",FLOOR($C15,10)) | I15: =IF(OR($G15="",$H15="",NOT(ISNUMBER($G15)),NOT(ISNUMBER($H15))),"",$H15-$G15)
B16: =IF($A16="","",IFERROR(IF(INDEX(Community_Register!$B$2:$B$402,MATCH($A16,Community_Register!$A$2:$A$402,0))="","",INDEX(Community_Register!$B$2:$B$402,MATCH($A16,Community_Register!$A$2:$A$402,0))),"")) | D16: =IF(OR($C16="",NOT(ISNUMBER($C16))),"",FLOOR($C16,10)) | I16: =IF(OR($G16="",$H16="",NOT(ISNUMBER($G16)),NOT(ISNUMBER($H16))),"",$H16-$G16)
B17: =IF($A17="","",IFERROR(IF(INDEX(Community_Register!$B$2:$B$402,MATCH($A17,Community_Register!$A$2:$A$402,0))="","",INDEX(Community_Register!$B$2:$B$402,MATCH($A17,Community_Register!$A$2:$A$402,0))),"")) | D17: =IF(OR($C17="",NOT(ISNUMBER($C17))),"",FLOOR($C17,10)) | I17: =IF(OR($G17="",$H17="",NOT(ISNUMBER($G17)),NOT(ISNUMBER($H17))),"",$H17-$G17)
B18: =IF($A18="","",IFERROR(IF(INDEX(Community_Register!$B$2:$B$402,MATCH($A18,Community_Register!$A$2:$A$402,0))="","",INDEX(Community_Register!$B$2:$B$402,MATCH($A18,Community_Register!$A$2:$A$402,0))),"")) | D18: =IF(OR($C18="",NOT(ISNUMBER($C18))),"",FLOOR($C18,10)) | I18: =IF(OR($G18="",$H18="",NOT(ISNUMBER($G18)),NOT(ISNUMBER($H18))),"",$H18-$G18)
B19: =IF($A19="","",IFERROR(IF(INDEX(Community_Register!$B$2:$B$402,MATCH($A19,Community_Register!$A$2:$A$402,0))="","",INDEX(Community_Register!$B$2:$B$402,MATCH($A19,Community_Register!$A$2:$A$402,0))),"")) | D19: =IF(OR($C19="",NOT(ISNUMBER($C19))),"",FLOOR($C19,10)) | I19: =IF(OR($G19="",$H19="",NOT(ISNUMBER($G19)),NOT(ISNUMBER($H19))),"",$H19-$G19)
B20: =IF($A20="","",IFERROR(IF(INDEX(Community_Register!$B$2:$B$402,MATCH($A20,Community_Register!$A$2:$A$402,0))="","",INDEX(Community_Register!$B$2:$B$402,MATCH($A20,Community_Register!$A$2:$A$402,0))),"")) | D20: =IF(OR($C20="",NOT(ISNUMBER($C20))),"",FLOOR($C20,10)) | I20: =IF(OR($G20="",$H20="",NOT(ISNUMBER($G20)),NOT(ISNUMBER($H20))),"",$H20-$G20)
B21: =IF($A21="","",IFERROR(IF(INDEX(Community_Register!$B$2:$B$402,MATCH($A21,Community_Register!$A$2:$A$402,0))="","",INDEX(Community_Register!$B$2:$B$402,MATCH($A21,Community_Register!$A$2:$A$402,0))),"")) | D21: =IF(OR($C21="",NOT(ISNUMBER($C21))),"",FLOOR($C21,10)) | I21: =IF(OR($G21="",$H21="",NOT(ISNUMBER($G21)),NOT(ISNUMBER($H21))),"",$H21-$G21)
B22: =IF($A22="","",IFERROR(IF(INDEX(Community_Register!$B$2:$B$402,MATCH($A22,Community_Register!$A$2:$A$402,0))="","",INDEX(Community_Register!$B$2:$B$402,MATCH($A22,Community_Register!$A$2:$A$402,0))),"")) | D22: =IF(OR($C22="",NOT(ISNUMBER($C22))),"",FLOOR($C22,10)) | I22: =IF(OR($G22="",$H22="",NOT(ISNUMBER($G22)),NOT(ISNUMBER($H22))),"",$H22-$G22)
B23: =IF($A23="","",IFERROR(IF(INDEX(Community_Register!$B$2:$B$402,MATCH($A23,Community_Register!$A$2:$A$402,0))="","",INDEX(Community_Register!$B$2:$B$402,MATCH($A23,Community_Register!$A$2:$A$402,0))),"")) | D23: =IF(OR($C23="",NOT(ISNUMBER($C23))),"",FLOOR($C23,10)) | I23: =IF(OR($G23="",$H23="",NOT(ISNUMBER($G23)),NOT(ISNUMBER($H23))),"",$H23-$G23)
... B402: =IF($A402="","",IFERROR(IF(INDEX(Community_Register!$B$2:$B$402,MATCH($A402,Community_Register!$A$2:$A$402,0))="","",INDEX(Community_Register!$B$2:$B$402,MATCH($A402,Community_Register!$A$2:$A$402,0))),"")) | D402: =IF(OR($C402="",NOT(ISNUMBER($C402))),"",FLOOR($C402,10)) | I402: =IF(OR($G402="",$H402="",NOT(ISNUMBER($G402)),NOT(ISNUMBER($H402))),"",$H402-$G402)

Sheet Polygon_Geometry
A1: site_id | B1: community_name | C1: polygon_area_ha | D1: polygon_file_id | E1: polygon_imagery_date | F1: polygon_imagery_source | G1: polygon_confidence | H1: below_minimum_flag | I1: reference_circle | J1: equal_area_circle_radius_m | K1: polygon_redrawn | L1: redraw_area_ha | M1: polygon_iou | N1: documentary_managed_area_ha | O1: documentary_area_basis | P1: area_ratio | Q1: area_agreement_tier | R1: agreement_note | S1: controls_translated | T1: drawn_by | U1: drawn_date | V1: redraw_date | W1: notes | Y1: THE MEASUREMENT GEOMETRY. This sheet, not the documentary area, defines the ground every metric is computed over.
B2: =IF($A2="","",IFERROR(IF(INDEX(Community_Register!$B$2:$B$402,MATCH($A2,Community_Register!$A$2:$A$402,0))="","",INDEX(Community_Register!$B$2:$B$402,MATCH($A2,Community_Register!$A$2:$A$402,0))),"")) | H2: =IF($C2="","",IF($C2<1,"yes","no")) | I2: =IF($C2="","",IF($C2<2.6,"r75",IF($C2<5.2,"r110",IF($C2<9.9,"r150",IF($C2<19.8,"r210","r300"))))) | J2: =IF($C2="","",ROUND(SQRT($C2*10000/PI()),1)) | N2: =IF($A2="","",IFERROR(IF(INDEX(Community_Register!$S$2:$S$402,MATCH($A2,Community_Register!$A$2:$A$402,0))="","",INDEX(Community_Register!$S$2:$S$402,MATCH($A2,Community_Register!$A$2:$A$402,0))),"")) | O2: =IF($A2="","",IFERROR(IF(INDEX(Community_Register!$V$2:$V$402,MATCH($A2,Community_Register!$A$2:$A$402,0))="","",INDEX(Community_Register!$V$2:$V$402,MATCH($A2,Community_Register!$A$2:$A$402,0))),"")) | P2: =IF(OR($C2="",$N2="",NOT(ISNUMBER($N2))),"",$N2/$C2) | Q2: =IF($C2="","",IF(OR($N2="",NOT(ISNUMBER($N2))),"B",IF(ABS($P2-1)<=0.3,"A",IF(OR($P2>2,$P2<0.5),"C","B"))))
B3: =IF($A3="","",IFERROR(IF(INDEX(Community_Register!$B$2:$B$402,MATCH($A3,Community_Register!$A$2:$A$402,0))="","",INDEX(Community_Register!$B$2:$B$402,MATCH($A3,Community_Register!$A$2:$A$402,0))),"")) | H3: =IF($C3="","",IF($C3<1,"yes","no")) | I3: =IF($C3="","",IF($C3<2.6,"r75",IF($C3<5.2,"r110",IF($C3<9.9,"r150",IF($C3<19.8,"r210","r300"))))) | J3: =IF($C3="","",ROUND(SQRT($C3*10000/PI()),1)) | N3: =IF($A3="","",IFERROR(IF(INDEX(Community_Register!$S$2:$S$402,MATCH($A3,Community_Register!$A$2:$A$402,0))="","",INDEX(Community_Register!$S$2:$S$402,MATCH($A3,Community_Register!$A$2:$A$402,0))),"")) | O3: =IF($A3="","",IFERROR(IF(INDEX(Community_Register!$V$2:$V$402,MATCH($A3,Community_Register!$A$2:$A$402,0))="","",INDEX(Community_Register!$V$2:$V$402,MATCH($A3,Community_Register!$A$2:$A$402,0))),"")) | P3: =IF(OR($C3="",$N3="",NOT(ISNUMBER($N3))),"",$N3/$C3) | Q3: =IF($C3="","",IF(OR($N3="",NOT(ISNUMBER($N3))),"B",IF(ABS($P3-1)<=0.3,"A",IF(OR($P3>2,$P3<0.5),"C","B")))) | Y3: YOU supply: polygon_area_ha, polygon_file_id, the imagery date and source, polygon_confidence, the redraw fields, agreement_note and controls_translated. Everything else on this sheet computes itself.
B4: =IF($A4="","",IFERROR(IF(INDEX(Community_Register!$B$2:$B$402,MATCH($A4,Community_Register!$A$2:$A$402,0))="","",INDEX(Community_Register!$B$2:$B$402,MATCH($A4,Community_Register!$A$2:$A$402,0))),"")) | H4: =IF($C4="","",IF($C4<1,"yes","no")) | I4: =IF($C4="","",IF($C4<2.6,"r75",IF($C4<5.2,"r110",IF($C4<9.9,"r150",IF($C4<19.8,"r210","r300"))))) | J4: =IF($C4="","",ROUND(SQRT($C4*10000/PI()),1)) | N4: =IF($A4="","",IFERROR(IF(INDEX(Community_Register!$S$2:$S$402,MATCH($A4,Community_Register!$A$2:$A$402,0))="","",INDEX(Community_Register!$S$2:$S$402,MATCH($A4,Community_Register!$A$2:$A$402,0))),"")) | O4: =IF($A4="","",IFERROR(IF(INDEX(Community_Register!$V$2:$V$402,MATCH($A4,Community_Register!$A$2:$A$402,0))="","",INDEX(Community_Register!$V$2:$V$402,MATCH($A4,Community_Register!$A$2:$A$402,0))),"")) | P4: =IF(OR($C4="",$N4="",NOT(ISNUMBER($N4))),"",$N4/$C4) | Q4: =IF($C4="","",IF(OR($N4="",NOT(ISNUMBER($N4))),"B",IF(ABS($P4-1)<=0.3,"A",IF(OR($P4>2,$P4<0.5),"C","B"))))
B5: =IF($A5="","",IFERROR(IF(INDEX(Community_Register!$B$2:$B$402,MATCH($A5,Community_Register!$A$2:$A$402,0))="","",INDEX(Community_Register!$B$2:$B$402,MATCH($A5,Community_Register!$A$2:$A$402,0))),"")) | H5: =IF($C5="","",IF($C5<1,"yes","no")) | I5: =IF($C5="","",IF($C5<2.6,"r75",IF($C5<5.2,"r110",IF($C5<9.9,"r150",IF($C5<19.8,"r210","r300"))))) | J5: =IF($C5="","",ROUND(SQRT($C5*10000/PI()),1)) | N5: =IF($A5="","",IFERROR(IF(INDEX(Community_Register!$S$2:$S$402,MATCH($A5,Community_Register!$A$2:$A$402,0))="","",INDEX(Community_Register!$S$2:$S$402,MATCH($A5,Community_Register!$A$2:$A$402,0))),"")) | O5: =IF($A5="","",IFERROR(IF(INDEX(Community_Register!$V$2:$V$402,MATCH($A5,Community_Register!$A$2:$A$402,0))="","",INDEX(Community_Register!$V$2:$V$402,MATCH($A5,Community_Register!$A$2:$A$402,0))),"")) | P5: =IF(OR($C5="",$N5="",NOT(ISNUMBER($N5))),"",$N5/$C5) | Q5: =IF($C5="","",IF(OR($N5="",NOT(ISNUMBER($N5))),"B",IF(ABS($P5-1)<=0.3,"A",IF(OR($P5>2,$P5<0.5),"C","B")))) | Y5: The four documentary columns are READ-ONLY LOOKUPS from Community_Register. They cannot be typed and cannot drift. Enter the documentary area once, there.
B6: =IF($A6="","",IFERROR(IF(INDEX(Community_Register!$B$2:$B$402,MATCH($A6,Community_Register!$A$2:$A$402,0))="","",INDEX(Community_Register!$B$2:$B$402,MATCH($A6,Community_Register!$A$2:$A$402,0))),"")) | H6: =IF($C6="","",IF($C6<1,"yes","no")) | I6: =IF($C6="","",IF($C6<2.6,"r75",IF($C6<5.2,"r110",IF($C6<9.9,"r150",IF($C6<19.8,"r210","r300"))))) | J6: =IF($C6="","",ROUND(SQRT($C6*10000/PI()),1)) | N6: =IF($A6="","",IFERROR(IF(INDEX(Community_Register!$S$2:$S$402,MATCH($A6,Community_Register!$A$2:$A$402,0))="","",INDEX(Community_Register!$S$2:$S$402,MATCH($A6,Community_Register!$A$2:$A$402,0))),"")) | O6: =IF($A6="","",IFERROR(IF(INDEX(Community_Register!$V$2:$V$402,MATCH($A6,Community_Register!$A$2:$A$402,0))="","",INDEX(Community_Register!$V$2:$V$402,MATCH($A6,Community_Register!$A$2:$A$402,0))),"")) | P6: =IF(OR($C6="",$N6="",NOT(ISNUMBER($N6))),"",$N6/$C6) | Q6: =IF($C6="","",IF(OR($N6="",NOT(ISNUMBER($N6))),"B",IF(ABS($P6-1)<=0.3,"A",IF(OR($P6>2,$P6<0.5),"C","B"))))
B7: =IF($A7="","",IFERROR(IF(INDEX(Community_Register!$B$2:$B$402,MATCH($A7,Community_Register!$A$2:$A$402,0))="","",INDEX(Community_Register!$B$2:$B$402,MATCH($A7,Community_Register!$A$2:$A$402,0))),"")) | H7: =IF($C7="","",IF($C7<1,"yes","no")) | I7: =IF($C7="","",IF($C7<2.6,"r75",IF($C7<5.2,"r110",IF($C7<9.9,"r150",IF($C7<19.8,"r210","r300"))))) | J7: =IF($C7="","",ROUND(SQRT($C7*10000/PI()),1)) | N7: =IF($A7="","",IFERROR(IF(INDEX(Community_Register!$S$2:$S$402,MATCH($A7,Community_Register!$A$2:$A$402,0))="","",INDEX(Community_Register!$S$2:$S$402,MATCH($A7,Community_Register!$A$2:$A$402,0))),"")) | O7: =IF($A7="","",IFERROR(IF(INDEX(Community_Register!$V$2:$V$402,MATCH($A7,Community_Register!$A$2:$A$402,0))="","",INDEX(Community_Register!$V$2:$V$402,MATCH($A7,Community_Register!$A$2:$A$402,0))),"")) | P7: =IF(OR($C7="",$N7="",NOT(ISNUMBER($N7))),"",$N7/$C7) | Q7: =IF($C7="","",IF(OR($N7="",NOT(ISNUMBER($N7))),"B",IF(ABS($P7-1)<=0.3,"A",IF(OR($P7>2,$P7<0.5),"C","B")))) | Y7: reference_circle is matched to the polygon's AREA — r75 under 2.6 ha, r110 to 5.2, r150 to 9.9, r210 to 19.8, r300 above. Rescaling a 2-hectare polygon against a 7-hectare reference distribution biases every score at that site, and nothing downstream would reveal it.
B8: =IF($A8="","",IFERROR(IF(INDEX(Community_Register!$B$2:$B$402,MATCH($A8,Community_Register!$A$2:$A$402,0))="","",INDEX(Community_Register!$B$2:$B$402,MATCH($A8,Community_Register!$A$2:$A$402,0))),"")) | H8: =IF($C8="","",IF($C8<1,"yes","no")) | I8: =IF($C8="","",IF($C8<2.6,"r75",IF($C8<5.2,"r110",IF($C8<9.9,"r150",IF($C8<19.8,"r210","r300"))))) | J8: =IF($C8="","",ROUND(SQRT($C8*10000/PI()),1)) | N8: =IF($A8="","",IFERROR(IF(INDEX(Community_Register!$S$2:$S$402,MATCH($A8,Community_Register!$A$2:$A$402,0))="","",INDEX(Community_Register!$S$2:$S$402,MATCH($A8,Community_Register!$A$2:$A$402,0))),"")) | O8: =IF($A8="","",IFERROR(IF(INDEX(Community_Register!$V$2:$V$402,MATCH($A8,Community_Register!$A$2:$A$402,0))="","",INDEX(Community_Register!$V$2:$V$402,MATCH($A8,Community_Register!$A$2:$A$402,0))),"")) | P8: =IF(OR($C8="",$N8="",NOT(ISNUMBER($N8))),"",$N8/$C8) | Q8: =IF($C8="","",IF(OR($N8="",NOT(ISNUMBER($N8))),"B",IF(ABS($P8-1)<=0.3,"A",IF(OR($P8>2,$P8<0.5),"C","B"))))
B9: =IF($A9="","",IFERROR(IF(INDEX(Community_Register!$B$2:$B$402,MATCH($A9,Community_Register!$A$2:$A$402,0))="","",INDEX(Community_Register!$B$2:$B$402,MATCH($A9,Community_Register!$A$2:$A$402,0))),"")) | H9: =IF($C9="","",IF($C9<1,"yes","no")) | I9: =IF($C9="","",IF($C9<2.6,"r75",IF($C9<5.2,"r110",IF($C9<9.9,"r150",IF($C9<19.8,"r210","r300"))))) | J9: =IF($C9="","",ROUND(SQRT($C9*10000/PI()),1)) | N9: =IF($A9="","",IFERROR(IF(INDEX(Community_Register!$S$2:$S$402,MATCH($A9,Community_Register!$A$2:$A$402,0))="","",INDEX(Community_Register!$S$2:$S$402,MATCH($A9,Community_Register!$A$2:$A$402,0))),"")) | O9: =IF($A9="","",IFERROR(IF(INDEX(Community_Register!$V$2:$V$402,MATCH($A9,Community_Register!$A$2:$A$402,0))="","",INDEX(Community_Register!$V$2:$V$402,MATCH($A9,Community_Register!$A$2:$A$402,0))),"")) | P9: =IF(OR($C9="",$N9="",NOT(ISNUMBER($N9))),"",$N9/$C9) | Q9: =IF($C9="","",IF(OR($N9="",NOT(ISNUMBER($N9))),"B",IF(ABS($P9-1)<=0.3,"A",IF(OR($P9>2,$P9<0.5),"C","B")))) | Y9: equal_area_circle_radius_m is sqrt(area/pi) in metres. It is the alternative measurement geometry for sensitivity check SC1: a circle of the SAME AREA as the polygon, so that SC1 isolates the effect of SHAPE alone. It is computed here rather than by hand.
B10: =IF($A10="","",IFERROR(IF(INDEX(Community_Register!$B$2:$B$402,MATCH($A10,Community_Register!$A$2:$A$402,0))="","",INDEX(Community_Register!$B$2:$B$402,MATCH($A10,Community_Register!$A$2:$A$402,0))),"")) | H10: =IF($C10="","",IF($C10<1,"yes","no")) | I10: =IF($C10="","",IF($C10<2.6,"r75",IF($C10<5.2,"r110",IF($C10<9.9,"r150",IF($C10<19.8,"r210","r300"))))) | J10: =IF($C10="","",ROUND(SQRT($C10*10000/PI()),1)) | N10: =IF($A10="","",IFERROR(IF(INDEX(Community_Register!$S$2:$S$402,MATCH($A10,Community_Register!$A$2:$A$402,0))="","",INDEX(Community_Register!$S$2:$S$402,MATCH($A10,Community_Register!$A$2:$A$402,0))),"")) | O10: =IF($A10="","",IFERROR(IF(INDEX(Community_Register!$V$2:$V$402,MATCH($A10,Community_Register!$A$2:$A$402,0))="","",INDEX(Community_Register!$V$2:$V$402,MATCH($A10,Community_Register!$A$2:$A$402,0))),"")) | P10: =IF(OR($C10="",$N10="",NOT(ISNUMBER($N10))),"",$N10/$C10) | Q10: =IF($C10="","",IF(OR($N10="",NOT(ISNUMBER($N10))),"B",IF(ABS($P10-1)<=0.3,"A",IF(OR($P10>2,$P10<0.5),"C","B"))))
B11: =IF($A11="","",IFERROR(IF(INDEX(Community_Register!$B$2:$B$402,MATCH($A11,Community_Register!$A$2:$A$402,0))="","",INDEX(Community_Register!$B$2:$B$402,MATCH($A11,Community_Register!$A$2:$A$402,0))),"")) | H11: =IF($C11="","",IF($C11<1,"yes","no")) | I11: =IF($C11="","",IF($C11<2.6,"r75",IF($C11<5.2,"r110",IF($C11<9.9,"r150",IF($C11<19.8,"r210","r300"))))) | J11: =IF($C11="","",ROUND(SQRT($C11*10000/PI()),1)) | N11: =IF($A11="","",IFERROR(IF(INDEX(Community_Register!$S$2:$S$402,MATCH($A11,Community_Register!$A$2:$A$402,0))="","",INDEX(Community_Register!$S$2:$S$402,MATCH($A11,Community_Register!$A$2:$A$402,0))),"")) | O11: =IF($A11="","",IFERROR(IF(INDEX(Community_Register!$V$2:$V$402,MATCH($A11,Community_Register!$A$2:$A$402,0))="","",INDEX(Community_Register!$V$2:$V$402,MATCH($A11,Community_Register!$A$2:$A$402,0))),"")) | P11: =IF(OR($C11="",$N11="",NOT(ISNUMBER($N11))),"",$N11/$C11) | Q11: =IF($C11="","",IF(OR($N11="",NOT(ISNUMBER($N11))),"B",IF(ABS($P11-1)<=0.3,"A",IF(OR($P11>2,$P11<0.5),"C","B")))) | Y11: area_agreement_tier: A within 30 per cent, B where there is no documentary figure or a gap of 30 to 100 per cent, C beyond a factor of two. A site with a polygon and no documentary figure is tier B, never blank. The polygon stands in every case — the tier records how well corroborated it is, not which number wins.
B12: =IF($A12="","",IFERROR(IF(INDEX(Community_Register!$B$2:$B$402,MATCH($A12,Community_Register!$A$2:$A$402,0))="","",INDEX(Community_Register!$B$2:$B$402,MATCH($A12,Community_Register!$A$2:$A$402,0))),"")) | H12: =IF($C12="","",IF($C12<1,"yes","no")) | I12: =IF($C12="","",IF($C12<2.6,"r75",IF($C12<5.2,"r110",IF($C12<9.9,"r150",IF($C12<19.8,"r210","r300"))))) | J12: =IF($C12="","",ROUND(SQRT($C12*10000/PI()),1)) | N12: =IF($A12="","",IFERROR(IF(INDEX(Community_Register!$S$2:$S$402,MATCH($A12,Community_Register!$A$2:$A$402,0))="","",INDEX(Community_Register!$S$2:$S$402,MATCH($A12,Community_Register!$A$2:$A$402,0))),"")) | O12: =IF($A12="","",IFERROR(IF(INDEX(Community_Register!$V$2:$V$402,MATCH($A12,Community_Register!$A$2:$A$402,0))="","",INDEX(Community_Register!$V$2:$V$402,MATCH($A12,Community_Register!$A$2:$A$402,0))),"")) | P12: =IF(OR($C12="",$N12="",NOT(ISNUMBER($N12))),"",$N12/$C12) | Q12: =IF($C12="","",IF(OR($N12="",NOT(ISNUMBER($N12))),"B",IF(ABS($P12-1)<=0.3,"A",IF(OR($P12>2,$P12<0.5),"C","B"))))
B13: =IF($A13="","",IFERROR(IF(INDEX(Community_Register!$B$2:$B$402,MATCH($A13,Community_Register!$A$2:$A$402,0))="","",INDEX(Community_Register!$B$2:$B$402,MATCH($A13,Community_Register!$A$2:$A$402,0))),"")) | H13: =IF($C13="","",IF($C13<1,"yes","no")) | I13: =IF($C13="","",IF($C13<2.6,"r75",IF($C13<5.2,"r110",IF($C13<9.9,"r150",IF($C13<19.8,"r210","r300"))))) | J13: =IF($C13="","",ROUND(SQRT($C13*10000/PI()),1)) | N13: =IF($A13="","",IFERROR(IF(INDEX(Community_Register!$S$2:$S$402,MATCH($A13,Community_Register!$A$2:$A$402,0))="","",INDEX(Community_Register!$S$2:$S$402,MATCH($A13,Community_Register!$A$2:$A$402,0))),"")) | O13: =IF($A13="","",IFERROR(IF(INDEX(Community_Register!$V$2:$V$402,MATCH($A13,Community_Register!$A$2:$A$402,0))="","",INDEX(Community_Register!$V$2:$V$402,MATCH($A13,Community_Register!$A$2:$A$402,0))),"")) | P13: =IF(OR($C13="",$N13="",NOT(ISNUMBER($N13))),"",$N13/$C13) | Q13: =IF($C13="","",IF(OR($N13="",NOT(ISNUMBER($N13))),"B",IF(ABS($P13-1)<=0.3,"A",IF(OR($P13>2,$P13<0.5),"C","B")))) | Y13: A gap beyond a factor of two usually has one cause: the source quoted the TOTAL HOLDING. The second commonest is a genuinely non-contiguous holding whose detached parcels the polygon excludes. parcel_structure on Community_Register is what separates the two. Record what you found in agreement_note.
B14: =IF($A14="","",IFERROR(IF(INDEX(Community_Register!$B$2:$B$402,MATCH($A14,Community_Register!$A$2:$A$402,0))="","",INDEX(Community_Register!$B$2:$B$402,MATCH($A14,Community_Register!$A$2:$A$402,0))),"")) | H14: =IF($C14="","",IF($C14<1,"yes","no")) | I14: =IF($C14="","",IF($C14<2.6,"r75",IF($C14<5.2,"r110",IF($C14<9.9,"r150",IF($C14<19.8,"r210","r300"))))) | J14: =IF($C14="","",ROUND(SQRT($C14*10000/PI()),1)) | N14: =IF($A14="","",IFERROR(IF(INDEX(Community_Register!$S$2:$S$402,MATCH($A14,Community_Register!$A$2:$A$402,0))="","",INDEX(Community_Register!$S$2:$S$402,MATCH($A14,Community_Register!$A$2:$A$402,0))),"")) | O14: =IF($A14="","",IFERROR(IF(INDEX(Community_Register!$V$2:$V$402,MATCH($A14,Community_Register!$A$2:$A$402,0))="","",INDEX(Community_Register!$V$2:$V$402,MATCH($A14,Community_Register!$A$2:$A$402,0))),"")) | P14: =IF(OR($C14="",$N14="",NOT(ISNUMBER($N14))),"",$N14/$C14) | Q14: =IF($C14="","",IF(OR($N14="",NOT(ISNUMBER($N14))),"B",IF(ABS($P14-1)<=0.3,"A",IF(OR($P14>2,$P14<0.5),"C","B"))))
B15: =IF($A15="","",IFERROR(IF(INDEX(Community_Register!$B$2:$B$402,MATCH($A15,Community_Register!$A$2:$A$402,0))="","",INDEX(Community_Register!$B$2:$B$402,MATCH($A15,Community_Register!$A$2:$A$402,0))),"")) | H15: =IF($C15="","",IF($C15<1,"yes","no")) | I15: =IF($C15="","",IF($C15<2.6,"r75",IF($C15<5.2,"r110",IF($C15<9.9,"r150",IF($C15<19.8,"r210","r300"))))) | J15: =IF($C15="","",ROUND(SQRT($C15*10000/PI()),1)) | N15: =IF($A15="","",IFERROR(IF(INDEX(Community_Register!$S$2:$S$402,MATCH($A15,Community_Register!$A$2:$A$402,0))="","",INDEX(Community_Register!$S$2:$S$402,MATCH($A15,Community_Register!$A$2:$A$402,0))),"")) | O15: =IF($A15="","",IFERROR(IF(INDEX(Community_Register!$V$2:$V$402,MATCH($A15,Community_Register!$A$2:$A$402,0))="","",INDEX(Community_Register!$V$2:$V$402,MATCH($A15,Community_Register!$A$2:$A$402,0))),"")) | P15: =IF(OR($C15="",$N15="",NOT(ISNUMBER($N15))),"",$N15/$C15) | Q15: =IF($C15="","",IF(OR($N15="",NOT(ISNUMBER($N15))),"B",IF(ABS($P15-1)<=0.3,"A",IF(OR($P15>2,$P15<0.5),"C","B")))) | Y15: MINIMUM 1.0 HECTARE. Below it the site falls back to a 75 m circle and is flagged; below_minimum_flag says so automatically.
B16: =IF($A16="","",IFERROR(IF(INDEX(Community_Register!$B$2:$B$402,MATCH($A16,Community_Register!$A$2:$A$402,0))="","",INDEX(Community_Register!$B$2:$B$402,MATCH($A16,Community_Register!$A$2:$A$402,0))),"")) | H16: =IF($C16="","",IF($C16<1,"yes","no")) | I16: =IF($C16="","",IF($C16<2.6,"r75",IF($C16<5.2,"r110",IF($C16<9.9,"r150",IF($C16<19.8,"r210","r300"))))) | J16: =IF($C16="","",ROUND(SQRT($C16*10000/PI()),1)) | N16: =IF($A16="","",IFERROR(IF(INDEX(Community_Register!$S$2:$S$402,MATCH($A16,Community_Register!$A$2:$A$402,0))="","",INDEX(Community_Register!$S$2:$S$402,MATCH($A16,Community_Register!$A$2:$A$402,0))),"")) | O16: =IF($A16="","",IFERROR(IF(INDEX(Community_Register!$V$2:$V$402,MATCH($A16,Community_Register!$A$2:$A$402,0))="","",INDEX(Community_Register!$V$2:$V$402,MATCH($A16,Community_Register!$A$2:$A$402,0))),"")) | P16: =IF(OR($C16="",$N16="",NOT(ISNUMBER($N16))),"",$N16/$C16) | Q16: =IF($C16="","",IF(OR($N16="",NOT(ISNUMBER($N16))),"B",IF(ABS($P16-1)<=0.3,"A",IF(OR($P16>2,$P16<0.5),"C","B"))))
B17: =IF($A17="","",IFERROR(IF(INDEX(Community_Register!$B$2:$B$402,MATCH($A17,Community_Register!$A$2:$A$402,0))="","",INDEX(Community_Register!$B$2:$B$402,MATCH($A17,Community_Register!$A$2:$A$402,0))),"")) | H17: =IF($C17="","",IF($C17<1,"yes","no")) | I17: =IF($C17="","",IF($C17<2.6,"r75",IF($C17<5.2,"r110",IF($C17<9.9,"r150",IF($C17<19.8,"r210","r300"))))) | J17: =IF($C17="","",ROUND(SQRT($C17*10000/PI()),1)) | N17: =IF($A17="","",IFERROR(IF(INDEX(Community_Register!$S$2:$S$402,MATCH($A17,Community_Register!$A$2:$A$402,0))="","",INDEX(Community_Register!$S$2:$S$402,MATCH($A17,Community_Register!$A$2:$A$402,0))),"")) | O17: =IF($A17="","",IFERROR(IF(INDEX(Community_Register!$V$2:$V$402,MATCH($A17,Community_Register!$A$2:$A$402,0))="","",INDEX(Community_Register!$V$2:$V$402,MATCH($A17,Community_Register!$A$2:$A$402,0))),"")) | P17: =IF(OR($C17="",$N17="",NOT(ISNUMBER($N17))),"",$N17/$C17) | Q17: =IF($C17="","",IF(OR($N17="",NOT(ISNUMBER($N17))),"B",IF(ABS($P17-1)<=0.3,"A",IF(OR($P17>2,$P17<0.5),"C","B"))))
B18: =IF($A18="","",IFERROR(IF(INDEX(Community_Register!$B$2:$B$402,MATCH($A18,Community_Register!$A$2:$A$402,0))="","",INDEX(Community_Register!$B$2:$B$402,MATCH($A18,Community_Register!$A$2:$A$402,0))),"")) | H18: =IF($C18="","",IF($C18<1,"yes","no")) | I18: =IF($C18="","",IF($C18<2.6,"r75",IF($C18<5.2,"r110",IF($C18<9.9,"r150",IF($C18<19.8,"r210","r300"))))) | J18: =IF($C18="","",ROUND(SQRT($C18*10000/PI()),1)) | N18: =IF($A18="","",IFERROR(IF(INDEX(Community_Register!$S$2:$S$402,MATCH($A18,Community_Register!$A$2:$A$402,0))="","",INDEX(Community_Register!$S$2:$S$402,MATCH($A18,Community_Register!$A$2:$A$402,0))),"")) | O18: =IF($A18="","",IFERROR(IF(INDEX(Community_Register!$V$2:$V$402,MATCH($A18,Community_Register!$A$2:$A$402,0))="","",INDEX(Community_Register!$V$2:$V$402,MATCH($A18,Community_Register!$A$2:$A$402,0))),"")) | P18: =IF(OR($C18="",$N18="",NOT(ISNUMBER($N18))),"",$N18/$C18) | Q18: =IF($C18="","",IF(OR($N18="",NOT(ISNUMBER($N18))),"B",IF(ABS($P18-1)<=0.3,"A",IF(OR($P18>2,$P18<0.5),"C","B"))))
B19: =IF($A19="","",IFERROR(IF(INDEX(Community_Register!$B$2:$B$402,MATCH($A19,Community_Register!$A$2:$A$402,0))="","",INDEX(Community_Register!$B$2:$B$402,MATCH($A19,Community_Register!$A$2:$A$402,0))),"")) | H19: =IF($C19="","",IF($C19<1,"yes","no")) | I19: =IF($C19="","",IF($C19<2.6,"r75",IF($C19<5.2,"r110",IF($C19<9.9,"r150",IF($C19<19.8,"r210","r300"))))) | J19: =IF($C19="","",ROUND(SQRT($C19*10000/PI()),1)) | N19: =IF($A19="","",IFERROR(IF(INDEX(Community_Register!$S$2:$S$402,MATCH($A19,Community_Register!$A$2:$A$402,0))="","",INDEX(Community_Register!$S$2:$S$402,MATCH($A19,Community_Register!$A$2:$A$402,0))),"")) | O19: =IF($A19="","",IFERROR(IF(INDEX(Community_Register!$V$2:$V$402,MATCH($A19,Community_Register!$A$2:$A$402,0))="","",INDEX(Community_Register!$V$2:$V$402,MATCH($A19,Community_Register!$A$2:$A$402,0))),"")) | P19: =IF(OR($C19="",$N19="",NOT(ISNUMBER($N19))),"",$N19/$C19) | Q19: =IF($C19="","",IF(OR($N19="",NOT(ISNUMBER($N19))),"B",IF(ABS($P19-1)<=0.3,"A",IF(OR($P19>2,$P19<0.5),"C","B"))))
B20: =IF($A20="","",IFERROR(IF(INDEX(Community_Register!$B$2:$B$402,MATCH($A20,Community_Register!$A$2:$A$402,0))="","",INDEX(Community_Register!$B$2:$B$402,MATCH($A20,Community_Register!$A$2:$A$402,0))),"")) | H20: =IF($C20="","",IF($C20<1,"yes","no")) | I20: =IF($C20="","",IF($C20<2.6,"r75",IF($C20<5.2,"r110",IF($C20<9.9,"r150",IF($C20<19.8,"r210","r300"))))) | J20: =IF($C20="","",ROUND(SQRT($C20*10000/PI()),1)) | N20: =IF($A20="","",IFERROR(IF(INDEX(Community_Register!$S$2:$S$402,MATCH($A20,Community_Register!$A$2:$A$402,0))="","",INDEX(Community_Register!$S$2:$S$402,MATCH($A20,Community_Register!$A$2:$A$402,0))),"")) | O20: =IF($A20="","",IFERROR(IF(INDEX(Community_Register!$V$2:$V$402,MATCH($A20,Community_Register!$A$2:$A$402,0))="","",INDEX(Community_Register!$V$2:$V$402,MATCH($A20,Community_Register!$A$2:$A$402,0))),"")) | P20: =IF(OR($C20="",$N20="",NOT(ISNUMBER($N20))),"",$N20/$C20) | Q20: =IF($C20="","",IF(OR($N20="",NOT(ISNUMBER($N20))),"B",IF(ABS($P20-1)<=0.3,"A",IF(OR($P20>2,$P20<0.5),"C","B"))))
B21: =IF($A21="","",IFERROR(IF(INDEX(Community_Register!$B$2:$B$402,MATCH($A21,Community_Register!$A$2:$A$402,0))="","",INDEX(Community_Register!$B$2:$B$402,MATCH($A21,Community_Register!$A$2:$A$402,0))),"")) | H21: =IF($C21="","",IF($C21<1,"yes","no")) | I21: =IF($C21="","",IF($C21<2.6,"r75",IF($C21<5.2,"r110",IF($C21<9.9,"r150",IF($C21<19.8,"r210","r300"))))) | J21: =IF($C21="","",ROUND(SQRT($C21*10000/PI()),1)) | N21: =IF($A21="","",IFERROR(IF(INDEX(Community_Register!$S$2:$S$402,MATCH($A21,Community_Register!$A$2:$A$402,0))="","",INDEX(Community_Register!$S$2:$S$402,MATCH($A21,Community_Register!$A$2:$A$402,0))),"")) | O21: =IF($A21="","",IFERROR(IF(INDEX(Community_Register!$V$2:$V$402,MATCH($A21,Community_Register!$A$2:$A$402,0))="","",INDEX(Community_Register!$V$2:$V$402,MATCH($A21,Community_Register!$A$2:$A$402,0))),"")) | P21: =IF(OR($C21="",$N21="",NOT(ISNUMBER($N21))),"",$N21/$C21) | Q21: =IF($C21="","",IF(OR($N21="",NOT(ISNUMBER($N21))),"B",IF(ABS($P21-1)<=0.3,"A",IF(OR($P21>2,$P21<0.5),"C","B"))))
B22: =IF($A22="","",IFERROR(IF(INDEX(Community_Register!$B$2:$B$402,MATCH($A22,Community_Register!$A$2:$A$402,0))="","",INDEX(Community_Register!$B$2:$B$402,MATCH($A22,Community_Register!$A$2:$A$402,0))),"")) | H22: =IF($C22="","",IF($C22<1,"yes","no")) | I22: =IF($C22="","",IF($C22<2.6,"r75",IF($C22<5.2,"r110",IF($C22<9.9,"r150",IF($C22<19.8,"r210","r300"))))) | J22: =IF($C22="","",ROUND(SQRT($C22*10000/PI()),1)) | N22: =IF($A22="","",IFERROR(IF(INDEX(Community_Register!$S$2:$S$402,MATCH($A22,Community_Register!$A$2:$A$402,0))="","",INDEX(Community_Register!$S$2:$S$402,MATCH($A22,Community_Register!$A$2:$A$402,0))),"")) | O22: =IF($A22="","",IFERROR(IF(INDEX(Community_Register!$V$2:$V$402,MATCH($A22,Community_Register!$A$2:$A$402,0))="","",INDEX(Community_Register!$V$2:$V$402,MATCH($A22,Community_Register!$A$2:$A$402,0))),"")) | P22: =IF(OR($C22="",$N22="",NOT(ISNUMBER($N22))),"",$N22/$C22) | Q22: =IF($C22="","",IF(OR($N22="",NOT(ISNUMBER($N22))),"B",IF(ABS($P22-1)<=0.3,"A",IF(OR($P22>2,$P22<0.5),"C","B"))))
B23: =IF($A23="","",IFERROR(IF(INDEX(Community_Register!$B$2:$B$402,MATCH($A23,Community_Register!$A$2:$A$402,0))="","",INDEX(Community_Register!$B$2:$B$402,MATCH($A23,Community_Register!$A$2:$A$402,0))),"")) | H23: =IF($C23="","",IF($C23<1,"yes","no")) | I23: =IF($C23="","",IF($C23<2.6,"r75",IF($C23<5.2,"r110",IF($C23<9.9,"r150",IF($C23<19.8,"r210","r300"))))) | J23: =IF($C23="","",ROUND(SQRT($C23*10000/PI()),1)) | N23: =IF($A23="","",IFERROR(IF(INDEX(Community_Register!$S$2:$S$402,MATCH($A23,Community_Register!$A$2:$A$402,0))="","",INDEX(Community_Register!$S$2:$S$402,MATCH($A23,Community_Register!$A$2:$A$402,0))),"")) | O23: =IF($A23="","",IFERROR(IF(INDEX(Community_Register!$V$2:$V$402,MATCH($A23,Community_Register!$A$2:$A$402,0))="","",INDEX(Community_Register!$V$2:$V$402,MATCH($A23,Community_Register!$A$2:$A$402,0))),"")) | P23: =IF(OR($C23="",$N23="",NOT(ISNUMBER($N23))),"",$N23/$C23) | Q23: =IF($C23="","",IF(OR($N23="",NOT(ISNUMBER($N23))),"B",IF(ABS($P23-1)<=0.3,"A",IF(OR($P23>2,$P23<0.5),"C","B"))))
B24: =IF($A24="","",IFERROR(IF(INDEX(Community_Register!$B$2:$B$402,MATCH($A24,Community_Register!$A$2:$A$402,0))="","",INDEX(Community_Register!$B$2:$B$402,MATCH($A24,Community_Register!$A$2:$A$402,0))),"")) | H24: =IF($C24="","",IF($C24<1,"yes","no")) | I24: =IF($C24="","",IF($C24<2.6,"r75",IF($C24<5.2,"r110",IF($C24<9.9,"r150",IF($C24<19.8,"r210","r300"))))) | J24: =IF($C24="","",ROUND(SQRT($C24*10000/PI()),1)) | N24: =IF($A24="","",IFERROR(IF(INDEX(Community_Register!$S$2:$S$402,MATCH($A24,Community_Register!$A$2:$A$402,0))="","",INDEX(Community_Register!$S$2:$S$402,MATCH($A24,Community_Register!$A$2:$A$402,0))),"")) | O24: =IF($A24="","",IFERROR(IF(INDEX(Community_Register!$V$2:$V$402,MATCH($A24,Community_Register!$A$2:$A$402,0))="","",INDEX(Community_Register!$V$2:$V$402,MATCH($A24,Community_Register!$A$2:$A$402,0))),"")) | P24: =IF(OR($C24="",$N24="",NOT(ISNUMBER($N24))),"",$N24/$C24) | Q24: =IF($C24="","",IF(OR($N24="",NOT(ISNUMBER($N24))),"B",IF(ABS($P24-1)<=0.3,"A",IF(OR($P24>2,$P24<0.5),"C","B"))))
B25: =IF($A25="","",IFERROR(IF(INDEX(Community_Register!$B$2:$B$402,MATCH($A25,Community_Register!$A$2:$A$402,0))="","",INDEX(Community_Register!$B$2:$B$402,MATCH($A25,Community_Register!$A$2:$A$402,0))),"")) | H25: =IF($C25="","",IF($C25<1,"yes","no")) | I25: =IF($C25="","",IF($C25<2.6,"r75",IF($C25<5.2,"r110",IF($C25<9.9,"r150",IF($C25<19.8,"r210","r300"))))) | J25: =IF($C25="","",ROUND(SQRT($C25*10000/PI()),1)) | N25: =IF($A25="","",IFERROR(IF(INDEX(Community_Register!$S$2:$S$402,MATCH($A25,Community_Register!$A$2:$A$402,0))="","",INDEX(Community_Register!$S$2:$S$402,MATCH($A25,Community_Register!$A$2:$A$402,0))),"")) | O25: =IF($A25="","",IFERROR(IF(INDEX(Community_Register!$V$2:$V$402,MATCH($A25,Community_Register!$A$2:$A$402,0))="","",INDEX(Community_Register!$V$2:$V$402,MATCH($A25,Community_Register!$A$2:$A$402,0))),"")) | P25: =IF(OR($C25="",$N25="",NOT(ISNUMBER($N25))),"",$N25/$C25) | Q25: =IF($C25="","",IF(OR($N25="",NOT(ISNUMBER($N25))),"B",IF(ABS($P25-1)<=0.3,"A",IF(OR($P25>2,$P25<0.5),"C","B"))))
B26: =IF($A26="","",IFERROR(IF(INDEX(Community_Register!$B$2:$B$402,MATCH($A26,Community_Register!$A$2:$A$402,0))="","",INDEX(Community_Register!$B$2:$B$402,MATCH($A26,Community_Register!$A$2:$A$402,0))),"")) | H26: =IF($C26="","",IF($C26<1,"yes","no")) | I26: =IF($C26="","",IF($C26<2.6,"r75",IF($C26<5.2,"r110",IF($C26<9.9,"r150",IF($C26<19.8,"r210","r300"))))) | J26: =IF($C26="","",ROUND(SQRT($C26*10000/PI()),1)) | N26: =IF($A26="","",IFERROR(IF(INDEX(Community_Register!$S$2:$S$402,MATCH($A26,Community_Register!$A$2:$A$402,0))="","",INDEX(Community_Register!$S$2:$S$402,MATCH($A26,Community_Register!$A$2:$A$402,0))),"")) | O26: =IF($A26="","",IFERROR(IF(INDEX(Community_Register!$V$2:$V$402,MATCH($A26,Community_Register!$A$2:$A$402,0))="","",INDEX(Community_Register!$V$2:$V$402,MATCH($A26,Community_Register!$A$2:$A$402,0))),"")) | P26: =IF(OR($C26="",$N26="",NOT(ISNUMBER($N26))),"",$N26/$C26) | Q26: =IF($C26="","",IF(OR($N26="",NOT(ISNUMBER($N26))),"B",IF(ABS($P26-1)<=0.3,"A",IF(OR($P26>2,$P26<0.5),"C","B"))))
B27: =IF($A27="","",IFERROR(IF(INDEX(Community_Register!$B$2:$B$402,MATCH($A27,Community_Register!$A$2:$A$402,0))="","",INDEX(Community_Register!$B$2:$B$402,MATCH($A27,Community_Register!$A$2:$A$402,0))),"")) | H27: =IF($C27="","",IF($C27<1,"yes","no")) | I27: =IF($C27="","",IF($C27<2.6,"r75",IF($C27<5.2,"r110",IF($C27<9.9,"r150",IF($C27<19.8,"r210","r300"))))) | J27: =IF($C27="","",ROUND(SQRT($C27*10000/PI()),1)) | N27: =IF($A27="","",IFERROR(IF(INDEX(Community_Register!$S$2:$S$402,MATCH($A27,Community_Register!$A$2:$A$402,0))="","",INDEX(Community_Register!$S$2:$S$402,MATCH($A27,Community_Register!$A$2:$A$402,0))),"")) | O27: =IF($A27="","",IFERROR(IF(INDEX(Community_Register!$V$2:$V$402,MATCH($A27,Community_Register!$A$2:$A$402,0))="","",INDEX(Community_Register!$V$2:$V$402,MATCH($A27,Community_Register!$A$2:$A$402,0))),"")) | P27: =IF(OR($C27="",$N27="",NOT(ISNUMBER($N27))),"",$N27/$C27) | Q27: =IF($C27="","",IF(OR($N27="",NOT(ISNUMBER($N27))),"B",IF(ABS($P27-1)<=0.3,"A",IF(OR($P27>2,$P27<0.5),"C","B"))))
... B402: =IF($A402="","",IFERROR(IF(INDEX(Community_Register!$B$2:$B$402,MATCH($A402,Community_Register!$A$2:$A$402,0))="","",INDEX(Community_Register!$B$2:$B$402,MATCH($A402,Community_Register!$A$2:$A$402,0))),"")) | H402: =IF($C402="","",IF($C402<1,"yes","no")) | I402: =IF($C402="","",IF($C402<2.6,"r75",IF($C402<5.2,"r110",IF($C402<9.9,"r150",IF($C402<19.8,"r210","r300"))))) | J402: =IF($C402="","",ROUND(SQRT($C402*10000/PI()),1)) | N402: =IF($A402="","",IFERROR(IF(INDEX(Community_Register!$S$2:$S$402,MATCH($A402,Community_Register!$A$2:$A$402,0))="","",INDEX(Community_Register!$S$2:$S$402,MATCH($A402,Community_Register!$A$2:$A$402,0))),"")) | O402: =IF($A402="","",IFERROR(IF(INDEX(Community_Register!$V$2:$V$402,MATCH($A402,Community_Register!$A$2:$A$402,0))="","",INDEX(Community_Register!$V$2:$V$402,MATCH($A402,Community_Register!$A$2:$A$402,0))),"")) | P402: =IF(OR($C402="",$N402="",NOT(ISNUMBER($N402))),"",$N402/$C402) | Q402: =IF($C402="","",IF(OR($N402="",NOT(ISNUMBER($N402))),"B",IF(ABS($P402-1)<=0.3,"A",IF(OR($P402>2,$P402<0.5),"C","B"))))

Sheet Source_Index
A1: source_id | B1: site_id | C1: source_class | D1: source_type | E1: title | F1: url_or_reference | G1: publication_or_snapshot_date | H1: retrieval_date | I1: full_text_or_abstract | J1: specific_passage_or_page | K1: value_supported | L1: source_language | M1: translation_used | N1: doi_or_identifier | O1: verified_resolves | P1: independence_group | Q1: notes | S1: ONE ROW PER SOURCE.
S3: verified_resolves is MANDATORY for every S1 and S2 source. Open the DOI or the repository record yourself. A fabricated academic citation looks like the strongest evidence in the record and will be believed.
S5: independence_group is a short id (G1, G2, G3) shared by every source deriving from the same underlying statement. Assign it as you read, not afterwards. A community's website, its own Facebook page and a directory listing copied from it are ONE group, however many URLs. A thesis, a grant record and a newspaper are three.
S7: The test: could this source be wrong in the same way as that one, for the same reason? If yes, same group.
S9: source_language is the language THIS SOURCE is written in. It is deliberately not called 'language': Source_Set records the language of an ADDRESS and Search_Log the language a SEARCH was run in, and three different quantities sharing one column name is how a merge silently produces nonsense.

Sheet Source_Set
A1: site_id | B1: address_id | C1: url | D1: platform_type | E1: supplied_or_discovered | F1: independence_group | G1: crawl_status | H1: pages_opened | I1: archive_checked | J1: archive_earliest_snapshot | K1: earliest_dated_item | L1: latest_dated_item | M1: yielded_fields | N1: address_language | O1: date_crawled | P1: coder_id | Q1: notes | S1: ONE ROW PER WEB ADDRESS PER COMMUNITY. Fill it BEFORE coding the community.
S3: Most communities have several addresses and they are not equivalent. A community's current site says what it wants said today; an abandoned domain, an old album or a directory listing captured in 2013 says what was true THEN. This study is about DATING, so the old material is usually worth more.
S5: crawl_status must never be left as 'not attempted' when a community is closed. An address that silently vanished from a search assistant's output was not crawled, whatever the rest of the response implies.
S7: 'blocked' is a real and reportable result. A guess about the content of a platform you could not open is fabrication.

Sheet Search_Log
A1: site_id | B1: database_or_source | C1: database_type | D1: search_strings_used | E1: search_language | F1: hits_returned | G1: full_text_opened | H1: abstract_only | I1: result | J1: date_searched | K1: coder_id | L1: notes | N1: ONE ROW PER DATABASE PER COMMUNITY — INCLUDING EVERY DATABASE THAT RETURNED NOTHING.
N3: This is the sheet that separates the three states the study must never confuse: EVIDENCE FOUND, EVIDENCE ABSENT after an adequately exhaustive search, and SEARCH INCOMPLETE. A row saying 'none found' in a named database is a finding. A missing row is not.
N5: Stages 5 and 6 — academic and grey literature — are now the study's HIGHEST-PRIORITY evidence route, because almost every rank-1 onset record lives there: a thesis that dates the fieldwork, a grant report that dates the project, a planning permit.
N7: Expect most academic searches to return nothing. In this population a handful of communities are well studied and the large majority have never been written about at all. Finding none is the normal and correct outcome.

Sheet Disagreement_Log
A1: disagreement_id | B1: site_id | C1: variable | D1: coder_1_value | E1: coder_2_value | F1: evidence_in_question | G1: rule_invoked | H1: resolution_type | I1: third_coder | J1: final_value | K1: definitions_amended | L1: re_coding_required | M1: date_resolved | N1: notes | P1: Every double-coding disagreement and its resolution.
P3: If definitions_amended = yes, the affected variable is re-coded IN FULL across every community already done. An amendment applied only to later communities makes the variable mean two different things in one column.

Sheet Reliability_Report
A1: variable | B1: variable_type | C1: agreement_method | D1: threshold_declared | E1: raw_agreement | F1: agreement_coefficient | G1: icc | H1: mean_absolute_difference | I1: within_uncertainty_band | J1: marginal_distribution_notes | K1: calibration_start | L1: calibration_midpoint | M1: calibration_end | N1: drift_result | O1: action_if_below_threshold | P1: notes | R1: PRE-FILLED with the fourteen variables the plan requires. Report reliability PER VARIABLE — never one figure for the whole exercise.
A2: e2_settlement_type | B2: categorical | C2: chance-corrected agreement | D2: declared before coding | O2: Revise the definition, re-code this variable in full, report both figures | P2: The highest-consequence categorical in Stage 1: a coding error here removes a community from the sample entirely.
A3: date_intervention_onset | B3: date | C3: ICC + mean absolute difference + agreement within band | D3: declared before coding | O3: Revise the definition, re-code this variable in full, report both figures | P3: Report MAD in YEARS beside the coefficient. | R3: v6 of this workbook listed twenty-four variables, thirteen of which were practice codes. Those are gone.
A4: onset_evidence_rank | B4: ordered categorical | C4: weighted chance-corrected agreement | D4: declared before coding | O4: Revise the definition, re-code this variable in full, report both figures | P4: Weights disagreements by distance between ranks.
A5: onset_confidence_tier | B5: ordered categorical | C5: weighted chance-corrected agreement | D5: declared before coding | O5: Revise the definition, re-code this variable in full, report both figures | P5: Load-bearing for cohort admission and decision D4.
A6: onset_proxy_flag | B6: categorical | C6: chance-corrected agreement | D6: declared before coding | O6: Revise the definition, re-code this variable in full, report both figures | P6: Determines which sites leave analysis A4.
